Workbook

Sheet DATA
A1: جمعه | B1: 14050620 | C1: 3073 | D1: مبینا سیدآبادی | E1: Tele sales | F1: 1 | G1: هادی | H1: بله | I1: پاسخ داده شده | J1: ندارد | K1: موجه و تأییدشده | L1: 46276 | M1: 60
A2: شنبه | B2: 14050621 | C2: 3082 | D2: حامد میرزایی | E2: Tele sales | F2: 0 | G2: مبینا | H2: روبیکا | I2: عدم پاسخ | J2: اختلال سامانه یا پیام‌رسان | K2: بدون دلیل موجه | L2: 46277
A3: یکشنبه | B3: 14050622 | C3: 3086 | D3: محمد توجهی | E3: Tele sales | F3: - | G3: شیدا | H3: ایتا | J3: خارج از ساعت کاری | K3: در انتظار بررسی | L3: 46278
A4: دوشنبه | B4: 14050623 | C4: 3090 | D4: هلیا هنرکار | E4: Tele sales | G4: هانیه | H4: تلگرام | J4: عدم دسترسی به اطلاعات ضروری | L4: 46279
A5: سه شنبه | B5: 14050624 | C5: 3095 | D5: مهناز جبارزاده | E5: Tele sales | H5: واتساپ | J5: حجم بالای پیام‌ها | L5: 46280
A6: چهارشنبه | B6: 14050625 | C6: 3097 | D6: جواهر باکودزفولی | E6: Tele sales | H6: پیامک | J6: فراموشی یا عدم پیگیری | L6: 46281
A7: پنجشنبه | B7: 14050626 | C7: 3109 | D7: پریناز ناظمیان پور | E7: Tele sales | J7: سایر | L7: 46282
A8: جمعه | B8: 14050627 | C8: 3110 | D8: آزاده فیروزی | E8: Tele sales | L8: 46283
A9: شنبه | B9: 14050628 | C9: 3127 | D9: سجاد موسوی | E9: Tele sales | L9: 46284
A10: یکشنبه | B10: 14050629 | C10: 3129 | D10: محمدایلیا ممانی | E10: Tele sales | L10: 46285
A11: دوشنبه | B11: 14050630 | C11: 3132 | D11: بردیا جانفشان | E11: Tele sales | L11: 46286
A12: سه شنبه | B12: 14050631 | C12: 3136 | D12: آتوسا آرامی | E12: Tele sales | L12: 46287
A13: چهارشنبه | B13: 14050701 | C13: 3140 | D13: آتنا نوربخش | E13: Tele sales | L13: 46288
A14: پنجشنبه | B14: 14050702 | C14: 3145 | D14: یگانه ویسی | E14: Tele sales | L14: 46289
A15: جمعه | B15: 14050703 | C15: 3165 | D15: مهتاب چراغی | E15: Tele sales | L15: 46290
A16: شنبه | B16: 14050704 | C16: 3196 | D16: محمدمهدی علیپور | E16: Tele sales | L16: 46291
A17: یکشنبه | B17: 14050705 | C17: 3204 | D17: هانیه معزز | E17: Tele sales | L17: 46292
A18: دوشنبه | B18: 14050706 | C18: 3212 | D18: آسیه احمدی فر | E18: Tele sales | L18: 46293
A19: سه شنبه | B19: 14050707 | C19: 3214 | D19: مهرداد سعیدمهدوی | E19: Tele sales | L19: 46294
... A33: سه شنبه | B33: 14050721 | C33: 3022 | D33: رعنا غیاثی‌نژاد | E33: MLM | L33: 46308
A34: چهارشنبه | B34: 14050722 | C34: 3246 | D34: محمد بوئینی | E34: MLM
A35: پنجشنبه | B35: 14050723 | C35: 3249 | D35: شاهین حسنی زاد | E35: MLM
A36: جمعه | B36: 14050724 | C36: 3065 | D36: نیوشا موسوی | E36: MLM
A37: شنبه | B37: 14050725 | C37: 3265 | D37: پوریا لرستانی | E37: MLM
A38: یکشنبه | B38: 14050726 | C38: 3172 | D38: الهه عسگری | E38: MLM
A39: دوشنبه | B39: 14050727 | C39: 3173 | D39: سمیرا شکیب | E39: MLM
A40: سه شنبه | B40: 14050728 | C40: 3248 | D40: سپهر فلاح دوست بدایی | E40: MLM
A41: چهارشنبه | B41: 14050729 | C41: 3245 | D41: مائده بهنامی‌فر | E41: MLM
A42: پنجشنبه | B42: 14050730 | C42: 3146 | D42: الهام شمس نیا | E42: Account
C43: 3111 | D43: ریحانه روح بخش | E43: Account
C44: 3081 | D44: سیما معصومی | E44: Account
C45: 3118 | D45: نرگس یوسفیان | E45: Account
C46: 3261 | D46: هانیه مظهری | E46: Account
C47: 3263 | D47: ترانه محمودی | E47: Account
C48: 3264 | D48: زینب میرزاده | E48: Account
C49: 3210 | D49: آیسان نورافکن | E49: Account
C50: 3155 | D50: پریا شیشه گر | E50: Account
C51: 3176 | D51: سیده متین سید حسینی | E51: Account
C52: 3067 | D52: عارفه ایزدان | E52: Account
C53: 3151 | D53: متین تدین خواه | E53: Account
...

Sheet Evaluations
Q1: 30 | R1: 30 | S1: 25 | T1: 15
A2: تاریخ بررسی | B2: کارشناس QC | C2: تاریخ دریافت پیام | E2: تاریخ پاسخدهی | G2: نام کارشناس | H2: تیم کارشناس | I2: پیامرسان | J2: ساعت دریافت | K2: ساعت پاسخ | L2: مدت زمان پاسخگویی | M2: وضعیت پاسخ | N2: دلیل تاخیر یا عدم پاسخ | O2: وضعیت رعایت یا عدم رعایت SLA | P2: وضعیت تایید دلیل | Q2: رعایت زمان پاسخ‌گویی (SLA) | R2: پیگیری و رسیدگی تا مشخص‌شدن نتیجه | S2: پایان‌بندی صحیح مکالمه | T2: لحن و نگارش حرفه‌ای | U2: نمره نهایی | V2: توضیحات کنترل کیفیت | W2: مبدل | X2: مبدل
A3: 14050621 | B3: هادی | C3: {=iferror(_xlfn.XLOOKUP(D3,DATA!B:B,DATA!A:A),"")} -> جمعه | D3: 14050620 | E3: {=iferror(_xlfn.XLOOKUP(F3,DATA!B:B,DATA!A:A),"")} -> سه شنبه | F3: 14050721 | G3: مبینا سیدآبادی | H3: {=_xlfn.XLOOKUP(G3,DATA!D:D,DATA!E:E,"")} -> Tele sales | I3: بله | J3: 0.5 | K3: 0.58333333 | W3: {=IF(D3="","",_xlfn.XLOOKUP(D3,DATA!B:B,DATA!L:L,""))} -> 46276 | X3: {=IF(F3="","",_xlfn.XLOOKUP(F3,DATA!B:B,DATA!L:L,""))} -> 46308
A4: 14050621 | B4: هادی | C4: {=iferror(_xlfn.XLOOKUP(D4,DATA!B:B,DATA!A:A),"")} -> شنبه | D4: 14050621 | E4: {=iferror(_xlfn.XLOOKUP(F4,DATA!B:B,DATA!A:A),"")} -> شنبه | F4: 14050621 | G4: مبینا سیدآبادی | H4: {=_xlfn.XLOOKUP(G4,DATA!D:D,DATA!E:E,"")} -> Tele sales | I4: بله | J4: 0.5 | K4: 0.58333333 | L4: =IF(OR(W4="",X4="",J4="",K4="",M4<>"پاسخ داده شده"),"", IF(X4+K4<W4+J4,"خطای تاریخ", LET( StartDT,W4+J4, EndDT,X4+K4, Days,SEQUENCE(X4-W4+1,1,W4), ROUND(1440*SUM(MAP(Days,LAMBDA(d, IF(OR(WEEKDAY(d,2)=4,WEEKDAY(d,2)=5),0, MAX(0,MIN(EndDT,d+TIME(18,0,0))- MAX(StartDT,d+TIME(9,0,0))) ) ))),0) ))) | O4: =IF(M4="","", IF(M4="عدم پاسخ","بدون پاسخ", IF(L4="","اطلاعات ناقص", IF(L4<=DATA!$M$1,"رعایت شده","رعایت نشده")))) | W4: {=IF(D4="","",_xlfn.XLOOKUP(D4,DATA!B:B,DATA!L:L,""))} -> 46277 | X4: {=IF(F4="","",_xlfn.XLOOKUP(F4,DATA!B:B,DATA!L:L,""))} -> 46277
A5: 14050621 | B5: هادی | C5: {=iferror(_xlfn.XLOOKUP(D5,DATA!B:B,DATA!A:A),"")} -> شنبه | D5: 14050621 | E5: {=iferror(_xlfn.XLOOKUP(F5,DATA!B:B,DATA!A:A),"")} -> شنبه | F5: 14050621 | G5: مبینا سیدآبادی | H5: {=_xlfn.XLOOKUP(G5,DATA!D:D,DATA!E:E,"")} -> Tele sales | I5: بله | J5: 0.625 | K5: 0.75 | L5: =IF(OR(W5="",X5="",J5="",K5="",M5<>"پاسخ داده شده"),"", IF(X5+K5<W5+J5,"خطای تاریخ", LET( StartDT,W5+J5, EndDT,X5+K5, Days,SEQUENCE(X5-W5+1,1,W5), ROUND(1440*SUM(MAP(Days,LAMBDA(d, IF(OR(WEEKDAY(d,2)=4,WEEKDAY(d,2)=5),0, MAX(0,MIN(EndDT,d+TIME(18,0,0))- MAX(StartDT,d+TIME(9,0,0))) ) ))),0) ))) | O5: =IF(M5="","", IF(M5="عدم پاسخ","بدون پاسخ", IF(L5="","اطلاعات ناقص", IF(L5<=DATA!$M$1,"رعایت شده","رعایت نشده")))) | W5: {=IF(D5="","",_xlfn.XLOOKUP(D5,DATA!B:B,DATA!L:L,""))} -> 46277 | X5: {=IF(F5="","",_xlfn.XLOOKUP(F5,DATA!B:B,DATA!L:L,""))} -> 46277
C6: {=iferror(_xlfn.XLOOKUP(D6,DATA!B:B,DATA!A:A),"")} | E6: {=iferror(_xlfn.XLOOKUP(F6,DATA!B:B,DATA!A:A),"")} | H6: {=_xlfn.XLOOKUP(G6,DATA!D:D,DATA!E:E,"")} | L6: =IF(OR(W6="",X6="",J6="",K6="",M6<>"پاسخ داده شده"),"", IF(X6+K6<W6+J6,"خطای تاریخ", LET( StartDT,W6+J6, EndDT,X6+K6, Days,SEQUENCE(X6-W6+1,1,W6), ROUND(1440*SUM(MAP(Days,LAMBDA(d, IF(OR(WEEKDAY(d,2)=4,WEEKDAY(d,2)=5),0, MAX(0,MIN(EndDT,d+TIME(18,0,0))- MAX(StartDT,d+TIME(9,0,0))) ) ))),0) ))) | O6: =IF(M6="","", IF(M6="عدم پاسخ","بدون پاسخ", IF(L6="","اطلاعات ناقص", IF(L6<=DATA!$M$1,"رعایت شده","رعایت نشده")))) | W6: {=IF(D6="","",_xlfn.XLOOKUP(D6,DATA!B:B,DATA!L:L,""))} | X6: {=IF(F6="","",_xlfn.XLOOKUP(F6,DATA!B:B,DATA!L:L,""))}
C7: {=iferror(_xlfn.XLOOKUP(D7,DATA!B:B,DATA!A:A),"")} | E7: {=iferror(_xlfn.XLOOKUP(F7,DATA!B:B,DATA!A:A),"")} | H7: {=_xlfn.XLOOKUP(G7,DATA!D:D,DATA!E:E,"")} | L7: =IF(OR(W7="",X7="",J7="",K7="",M7<>"پاسخ داده شده"),"", IF(X7+K7<W7+J7,"خطای تاریخ", LET( StartDT,W7+J7, EndDT,X7+K7, Days,SEQUENCE(X7-W7+1,1,W7), ROUND(1440*SUM(MAP(Days,LAMBDA(d, IF(OR(WEEKDAY(d,2)=4,WEEKDAY(d,2)=5),0, MAX(0,MIN(EndDT,d+TIME(18,0,0))- MAX(StartDT,d+TIME(9,0,0))) ) ))),0) ))) | O7: =IF(M7="","", IF(M7="عدم پاسخ","بدون پاسخ", IF(L7="","اطلاعات ناقص", IF(L7<=DATA!$M$1,"رعایت شده","رعایت نشده")))) | W7: {=IF(D7="","",_xlfn.XLOOKUP(D7,DATA!B:B,DATA!L:L,""))} | X7: {=IF(F7="","",_xlfn.XLOOKUP(F7,DATA!B:B,DATA!L:L,""))}
C8: {=iferror(_xlfn.XLOOKUP(D8,DATA!B:B,DATA!A:A),"")} | E8: {=iferror(_xlfn.XLOOKUP(F8,DATA!B:B,DATA!A:A),"")} | H8: {=_xlfn.XLOOKUP(G8,DATA!D:D,DATA!E:E,"")} | L8: =IF(OR(W8="",X8="",J8="",K8="",M8<>"پاسخ داده شده"),"", IF(X8+K8<W8+J8,"خطای تاریخ", LET( StartDT,W8+J8, EndDT,X8+K8, Days,SEQUENCE(X8-W8+1,1,W8), ROUND(1440*SUM(MAP(Days,LAMBDA(d, IF(OR(WEEKDAY(d,2)=4,WEEKDAY(d,2)=5),0, MAX(0,MIN(EndDT,d+TIME(18,0,0))- MAX(StartDT,d+TIME(9,0,0))) ) ))),0) ))) | O8: =IF(M8="","", IF(M8="عدم پاسخ","بدون پاسخ", IF(L8="","اطلاعات ناقص", IF(L8<=DATA!$M$1,"رعایت شده","رعایت نشده")))) | W8: {=IF(D8="","",_xlfn.XLOOKUP(D8,DATA!B:B,DATA!L:L,""))} | X8: {=IF(F8="","",_xlfn.XLOOKUP(F8,DATA!B:B,DATA!L:L,""))}
C9: {=iferror(_xlfn.XLOOKUP(D9,DATA!B:B,DATA!A:A),"")} | E9: {=iferror(_xlfn.XLOOKUP(F9,DATA!B:B,DATA!A:A),"")} | H9: {=_xlfn.XLOOKUP(G9,DATA!D:D,DATA!E:E,"")} | L9: =IF(OR(W9="",X9="",J9="",K9="",M9<>"پاسخ داده شده"),"", IF(X9+K9<W9+J9,"خطای تاریخ", LET( StartDT,W9+J9, EndDT,X9+K9, Days,SEQUENCE(X9-W9+1,1,W9), ROUND(1440*SUM(MAP(Days,LAMBDA(d, IF(OR(WEEKDAY(d,2)=4,WEEKDAY(d,2)=5),0, MAX(0,MIN(EndDT,d+TIME(18,0,0))- MAX(StartDT,d+TIME(9,0,0))) ) ))),0) ))) | O9: =IF(M9="","", IF(M9="عدم پاسخ","بدون پاسخ", IF(L9="","اطلاعات ناقص", IF(L9<=DATA!$M$1,"رعایت شده","رعایت نشده")))) | W9: {=IF(D9="","",_xlfn.XLOOKUP(D9,DATA!B:B,DATA!L:L,""))} | X9: {=IF(F9="","",_xlfn.XLOOKUP(F9,DATA!B:B,DATA!L:L,""))}
C10: {=iferror(_xlfn.XLOOKUP(D10,DATA!B:B,DATA!A:A),"")} | E10: {=iferror(_xlfn.XLOOKUP(F10,DATA!B:B,DATA!A:A),"")} | H10: {=_xlfn.XLOOKUP(G10,DATA!D:D,DATA!E:E,"")} | L10: =IF(OR(W10="",X10="",J10="",K10="",M10<>"پاسخ داده شده"),"", IF(X10+K10<W10+J10,"خطای تاریخ", LET( StartDT,W10+J10, EndDT,X10+K10, Days,SEQUENCE(X10-W10+1,1,W10), ROUND(1440*SUM(MAP(Days,LAMBDA(d, IF(OR(WEEKDAY(d,2)=4,WEEKDAY(d,2)=5),0, MAX(0,MIN(EndDT,d+TIME(18,0,0))- MAX(StartDT,d+TIME(9,0,0))) ) ))),0) ))) | O10: =IF(M10="","", IF(M10="عدم پاسخ","بدون پاسخ", IF(L10="","اطلاعات ناقص", IF(L10<=DATA!$M$1,"رعایت شده","رعایت نشده")))) | W10: {=IF(D10="","",_xlfn.XLOOKUP(D10,DATA!B:B,DATA!L:L,""))} | X10: {=IF(F10="","",_xlfn.XLOOKUP(F10,DATA!B:B,DATA!L:L,""))}
C11: {=iferror(_xlfn.XLOOKUP(D11,DATA!B:B,DATA!A:A),"")} | E11: {=iferror(_xlfn.XLOOKUP(F11,DATA!B:B,DATA!A:A),"")} | H11: {=_xlfn.XLOOKUP(G11,DATA!D:D,DATA!E:E,"")} | L11: =IF(OR(W11="",X11="",J11="",K11="",M11<>"پاسخ داده شده"),"", IF(X11+K11<W11+J11,"خطای تاریخ", LET( StartDT,W11+J11, EndDT,X11+K11, Days,SEQUENCE(X11-W11+1,1,W11), ROUND(1440*SUM(MAP(Days,LAMBDA(d, IF(OR(WEEKDAY(d,2)=4,WEEKDAY(d,2)=5),0, MAX(0,MIN(EndDT,d+TIME(18,0,0))- MAX(StartDT,d+TIME(9,0,0))) ) ))),0) ))) | O11: =IF(M11="","", IF(M11="عدم پاسخ","بدون پاسخ", IF(L11="","اطلاعات ناقص", IF(L11<=DATA!$M$1,"رعایت شده","رعایت نشده")))) | W11: {=IF(D11="","",_xlfn.XLOOKUP(D11,DATA!B:B,DATA!L:L,""))} | X11: {=IF(F11="","",_xlfn.XLOOKUP(F11,DATA!B:B,DATA!L:L,""))}
C12: {=iferror(_xlfn.XLOOKUP(D12,DATA!B:B,DATA!A:A),"")} | E12: {=iferror(_xlfn.XLOOKUP(F12,DATA!B:B,DATA!A:A),"")} | H12: {=_xlfn.XLOOKUP(G12,DATA!D:D,DATA!E:E,"")} | L12: =IF(OR(W12="",X12="",J12="",K12="",M12<>"پاسخ داده شده"),"", IF(X12+K12<W12+J12,"خطای تاریخ", LET( StartDT,W12+J12, EndDT,X12+K12, Days,SEQUENCE(X12-W12+1,1,W12), ROUND(1440*SUM(MAP(Days,LAMBDA(d, IF(OR(WEEKDAY(d,2)=4,WEEKDAY(d,2)=5),0, MAX(0,MIN(EndDT,d+TIME(18,0,0))- MAX(StartDT,d+TIME(9,0,0))) ) ))),0) ))) | O12: =IF(M12="","", IF(M12="عدم پاسخ","بدون پاسخ", IF(L12="","اطلاعات ناقص", IF(L12<=DATA!$M$1,"رعایت شده","رعایت نشده")))) | W12: {=IF(D12="","",_xlfn.XLOOKUP(D12,DATA!B:B,DATA!L:L,""))} | X12: {=IF(F12="","",_xlfn.XLOOKUP(F12,DATA!B:B,DATA!L:L,""))}
C13: {=iferror(_xlfn.XLOOKUP(D13,DATA!B:B,DATA!A:A),"")} | E13: {=iferror(_xlfn.XLOOKUP(F13,DATA!B:B,DATA!A:A),"")} | H13: {=_xlfn.XLOOKUP(G13,DATA!D:D,DATA!E:E,"")} | L13: =IF(OR(W13="",X13="",J13="",K13="",M13<>"پاسخ داده شده"),"", IF(X13+K13<W13+J13,"خطای تاریخ", LET( StartDT,W13+J13, EndDT,X13+K13, Days,SEQUENCE(X13-W13+1,1,W13), ROUND(1440*SUM(MAP(Days,LAMBDA(d, IF(OR(WEEKDAY(d,2)=4,WEEKDAY(d,2)=5),0, MAX(0,MIN(EndDT,d+TIME(18,0,0))- MAX(StartDT,d+TIME(9,0,0))) ) ))),0) ))) | O13: =IF(M13="","", IF(M13="عدم پاسخ","بدون پاسخ", IF(L13="","اطلاعات ناقص", IF(L13<=DATA!$M$1,"رعایت شده","رعایت نشده")))) | W13: {=IF(D13="","",_xlfn.XLOOKUP(D13,DATA!B:B,DATA!L:L,""))} | X13: {=IF(F13="","",_xlfn.XLOOKUP(F13,DATA!B:B,DATA!L:L,""))}
C14: {=iferror(_xlfn.XLOOKUP(D14,DATA!B:B,DATA!A:A),"")} | E14: {=iferror(_xlfn.XLOOKUP(F14,DATA!B:B,DATA!A:A),"")} | H14: {=_xlfn.XLOOKUP(G14,DATA!D:D,DATA!E:E,"")} | L14: =IF(OR(W14="",X14="",J14="",K14="",M14<>"پاسخ داده شده"),"", IF(X14+K14<W14+J14,"خطای تاریخ", LET( StartDT,W14+J14, EndDT,X14+K14, Days,SEQUENCE(X14-W14+1,1,W14), ROUND(1440*SUM(MAP(Days,LAMBDA(d, IF(OR(WEEKDAY(d,2)=4,WEEKDAY(d,2)=5),0, MAX(0,MIN(EndDT,d+TIME(18,0,0))- MAX(StartDT,d+TIME(9,0,0))) ) ))),0) ))) | O14: =IF(M14="","", IF(M14="عدم پاسخ","بدون پاسخ", IF(L14="","اطلاعات ناقص", IF(L14<=DATA!$M$1,"رعایت شده","رعایت نشده")))) | W14: {=IF(D14="","",_xlfn.XLOOKUP(D14,DATA!B:B,DATA!L:L,""))} | X14: {=IF(F14="","",_xlfn.XLOOKUP(F14,DATA!B:B,DATA!L:L,""))}
C15: {=iferror(_xlfn.XLOOKUP(D15,DATA!B:B,DATA!A:A),"")} | E15: {=iferror(_xlfn.XLOOKUP(F15,DATA!B:B,DATA!A:A),"")} | H15: {=_xlfn.XLOOKUP(G15,DATA!D:D,DATA!E:E,"")} | L15: =IF(OR(W15="",X15="",J15="",K15="",M15<>"پاسخ داده شده"),"", IF(X15+K15<W15+J15,"خطای تاریخ", LET( StartDT,W15+J15, EndDT,X15+K15, Days,SEQUENCE(X15-W15+1,1,W15), ROUND(1440*SUM(MAP(Days,LAMBDA(d, IF(OR(WEEKDAY(d,2)=4,WEEKDAY(d,2)=5),0, MAX(0,MIN(EndDT,d+TIME(18,0,0))- MAX(StartDT,d+TIME(9,0,0))) ) ))),0) ))) | O15: =IF(M15="","", IF(M15="عدم پاسخ","بدون پاسخ", IF(L15="","اطلاعات ناقص", IF(L15<=DATA!$M$1,"رعایت شده","رعایت نشده")))) | W15: {=IF(D15="","",_xlfn.XLOOKUP(D15,DATA!B:B,DATA!L:L,""))} | X15: {=IF(F15="","",_xlfn.XLOOKUP(F15,DATA!B:B,DATA!L:L,""))}
C16: {=iferror(_xlfn.XLOOKUP(D16,DATA!B:B,DATA!A:A),"")} | E16: {=iferror(_xlfn.XLOOKUP(F16,DATA!B:B,DATA!A:A),"")} | H16: {=_xlfn.XLOOKUP(G16,DATA!D:D,DATA!E:E,"")} | L16: =IF(OR(W16="",X16="",J16="",K16="",M16<>"پاسخ داده شده"),"", IF(X16+K16<W16+J16,"خطای تاریخ", LET( StartDT,W16+J16, EndDT,X16+K16, Days,SEQUENCE(X16-W16+1,1,W16), ROUND(1440*SUM(MAP(Days,LAMBDA(d, IF(OR(WEEKDAY(d,2)=4,WEEKDAY(d,2)=5),0, MAX(0,MIN(EndDT,d+TIME(18,0,0))- MAX(StartDT,d+TIME(9,0,0))) ) ))),0) ))) | O16: =IF(M16="","", IF(M16="عدم پاسخ","بدون پاسخ", IF(L16="","اطلاعات ناقص", IF(L16<=DATA!$M$1,"رعایت شده","رعایت نشده")))) | W16: {=IF(D16="","",_xlfn.XLOOKUP(D16,DATA!B:B,DATA!L:L,""))} | X16: {=IF(F16="","",_xlfn.XLOOKUP(F16,DATA!B:B,DATA!L:L,""))}
C17: {=iferror(_xlfn.XLOOKUP(D17,DATA!B:B,DATA!A:A),"")} | E17: {=iferror(_xlfn.XLOOKUP(F17,DATA!B:B,DATA!A:A),"")} | H17: {=_xlfn.XLOOKUP(G17,DATA!D:D,DATA!E:E,"")} | L17: =IF(OR(W17="",X17="",J17="",K17="",M17<>"پاسخ داده شده"),"", IF(X17+K17<W17+J17,"خطای تاریخ", LET( StartDT,W17+J17, EndDT,X17+K17, Days,SEQUENCE(X17-W17+1,1,W17), ROUND(1440*SUM(MAP(Days,LAMBDA(d, IF(OR(WEEKDAY(d,2)=4,WEEKDAY(d,2)=5),0, MAX(0,MIN(EndDT,d+TIME(18,0,0))- MAX(StartDT,d+TIME(9,0,0))) ) ))),0) ))) | O17: =IF(M17="","", IF(M17="عدم پاسخ","بدون پاسخ", IF(L17="","اطلاعات ناقص", IF(L17<=DATA!$M$1,"رعایت شده","رعایت نشده")))) | W17: {=IF(D17="","",_xlfn.XLOOKUP(D17,DATA!B:B,DATA!L:L,""))} | X17: {=IF(F17="","",_xlfn.XLOOKUP(F17,DATA!B:B,DATA!L:L,""))}
... C259: {=iferror(_xlfn.XLOOKUP(D259,DATA!B:B,DATA!A:A),"")} | E259: {=iferror(_xlfn.XLOOKUP(F259,DATA!B:B,DATA!A:A),"")} | H259: {=_xlfn.XLOOKUP(G259,DATA!D:D,DATA!E:E,"")} | L259: =IF(OR(W259="",X259="",J259="",K259="",M259<>"پاسخ داده شده"),"", IF(X259+K259<W259+J259,"خطای تاریخ", LET( StartDT,W259+J259, EndDT,X259+K259, Days,SEQUENCE(X259-W259+1,1,W259), ROUND(1440*SUM(MAP(Days,LAMBDA(d, IF(OR(WEEKDAY(d,2)=4,WEEKDAY(d,2)=5),0, MAX(0,MIN(EndDT,d+TIME(18,0,0))- MAX(StartDT,d+TIME(9,0,0))) ) ))),0) ))) | O259: =IF(M259="","", IF(M259="عدم پاسخ","بدون پاسخ", IF(L259="","اطلاعات ناقص", IF(L259<=DATA!$M$1,"رعایت شده","رعایت نشده")))) | W259: {=IF(D259="","",_xlfn.XLOOKUP(D259,DATA!B:B,DATA!L:L,""))} | X259: {=IF(F259="","",_xlfn.XLOOKUP(F259,DATA!B:B,DATA!L:L,""))}
C260: {=iferror(_xlfn.XLOOKUP(D260,DATA!B:B,DATA!A:A),"")} | H260: {=_xlfn.XLOOKUP(G260,DATA!D:D,DATA!E:E,"")} | L260: =IF(OR(W260="",X260="",J260="",K260="",M260<>"پاسخ داده شده"),"", IF(X260+K260<W260+J260,"خطای تاریخ", LET( StartDT,W260+J260, EndDT,X260+K260, Days,SEQUENCE(X260-W260+1,1,W260), ROUND(1440*SUM(MAP(Days,LAMBDA(d, IF(OR(WEEKDAY(d,2)=4,WEEKDAY(d,2)=5),0, MAX(0,MIN(EndDT,d+TIME(18,0,0))- MAX(StartDT,d+TIME(9,0,0))) ) ))),0) ))) | O260: =IF(M260="","", IF(M260="عدم پاسخ","بدون پاسخ", IF(L260="","اطلاعات ناقص", IF(L260<=DATA!$M$1,"رعایت شده","رعایت نشده")))) | W260: {=IF(D260="","",_xlfn.XLOOKUP(D260,DATA!B:B,DATA!L:L,""))} | X260: {=IF(F260="","",_xlfn.XLOOKUP(F260,DATA!B:B,DATA!L:L,""))}
C261: {=iferror(_xlfn.XLOOKUP(D261,DATA!B:B,DATA!A:A),"")} | H261: {=_xlfn.XLOOKUP(G261,DATA!D:D,DATA!E:E,"")} | L261: =IF(OR(W261="",X261="",J261="",K261="",M261<>"پاسخ داده شده"),"", IF(X261+K261<W261+J261,"خطای تاریخ", LET( StartDT,W261+J261, EndDT,X261+K261, Days,SEQUENCE(X261-W261+1,1,W261), ROUND(1440*SUM(MAP(Days,LAMBDA(d, IF(OR(WEEKDAY(d,2)=4,WEEKDAY(d,2)=5),0, MAX(0,MIN(EndDT,d+TIME(18,0,0))- MAX(StartDT,d+TIME(9,0,0))) ) ))),0) ))) | O261: =IF(M261="","", IF(M261="عدم پاسخ","بدون پاسخ", IF(L261="","اطلاعات ناقص", IF(L261<=DATA!$M$1,"رعایت شده","رعایت نشده")))) | W261: {=IF(D261="","",_xlfn.XLOOKUP(D261,DATA!B:B,DATA!L:L,""))} | X261: {=IF(F261="","",_xlfn.XLOOKUP(F261,DATA!B:B,DATA!L:L,""))}
C262: {=iferror(_xlfn.XLOOKUP(D262,DATA!B:B,DATA!A:A),"")} | H262: {=_xlfn.XLOOKUP(G262,DATA!D:D,DATA!E:E,"")} | L262: =IF(OR(W262="",X262="",J262="",K262="",M262<>"پاسخ داده شده"),"", IF(X262+K262<W262+J262,"خطای تاریخ", LET( StartDT,W262+J262, EndDT,X262+K262, Days,SEQUENCE(X262-W262+1,1,W262), ROUND(1440*SUM(MAP(Days,LAMBDA(d, IF(OR(WEEKDAY(d,2)=4,WEEKDAY(d,2)=5),0, MAX(0,MIN(EndDT,d+TIME(18,0,0))- MAX(StartDT,d+TIME(9,0,0))) ) ))),0) ))) | O262: =IF(M262="","", IF(M262="عدم پاسخ","بدون پاسخ", IF(L262="","اطلاعات ناقص", IF(L262<=DATA!$M$1,"رعایت شده","رعایت نشده")))) | W262: {=IF(D262="","",_xlfn.XLOOKUP(D262,DATA!B:B,DATA!L:L,""))} | X262: {=IF(F262="","",_xlfn.XLOOKUP(F262,DATA!B:B,DATA!L:L,""))}
C263: {=iferror(_xlfn.XLOOKUP(D263,DATA!B:B,DATA!A:A),"")} | H263: {=_xlfn.XLOOKUP(G263,DATA!D:D,DATA!E:E,"")} | L263: =IF(OR(W263="",X263="",J263="",K263="",M263<>"پاسخ داده شده"),"", IF(X263+K263<W263+J263,"خطای تاریخ", LET( StartDT,W263+J263, EndDT,X263+K263, Days,SEQUENCE(X263-W263+1,1,W263), ROUND(1440*SUM(MAP(Days,LAMBDA(d, IF(OR(WEEKDAY(d,2)=4,WEEKDAY(d,2)=5),0, MAX(0,MIN(EndDT,d+TIME(18,0,0))- MAX(StartDT,d+TIME(9,0,0))) ) ))),0) ))) | O263: =IF(M263="","", IF(M263="عدم پاسخ","بدون پاسخ", IF(L263="","اطلاعات ناقص", IF(L263<=DATA!$M$1,"رعایت شده","رعایت نشده")))) | W263: {=IF(D263="","",_xlfn.XLOOKUP(D263,DATA!B:B,DATA!L:L,""))} | X263: {=IF(F263="","",_xlfn.XLOOKUP(F263,DATA!B:B,DATA!L:L,""))}
C264: {=iferror(_xlfn.XLOOKUP(D264,DATA!B:B,DATA!A:A),"")} | H264: {=_xlfn.XLOOKUP(G264,DATA!D:D,DATA!E:E,"")} | L264: =IF(OR(W264="",X264="",J264="",K264="",M264<>"پاسخ داده شده"),"", IF(X264+K264<W264+J264,"خطای تاریخ", LET( StartDT,W264+J264, EndDT,X264+K264, Days,SEQUENCE(X264-W264+1,1,W264), ROUND(1440*SUM(MAP(Days,LAMBDA(d, IF(OR(WEEKDAY(d,2)=4,WEEKDAY(d,2)=5),0, MAX(0,MIN(EndDT,d+TIME(18,0,0))- MAX(StartDT,d+TIME(9,0,0))) ) ))),0) ))) | O264: =IF(M264="","", IF(M264="عدم پاسخ","بدون پاسخ", IF(L264="","اطلاعات ناقص", IF(L264<=DATA!$M$1,"رعایت شده","رعایت نشده")))) | W264: {=IF(D264="","",_xlfn.XLOOKUP(D264,DATA!B:B,DATA!L:L,""))} | X264: {=IF(F264="","",_xlfn.XLOOKUP(F264,DATA!B:B,DATA!L:L,""))}
C265: {=iferror(_xlfn.XLOOKUP(D265,DATA!B:B,DATA!A:A),"")} | H265: {=_xlfn.XLOOKUP(G265,DATA!D:D,DATA!E:E,"")} | L265: =IF(OR(W265="",X265="",J265="",K265="",M265<>"پاسخ داده شده"),"", IF(X265+K265<W265+J265,"خطای تاریخ", LET( StartDT,W265+J265, EndDT,X265+K265, Days,SEQUENCE(X265-W265+1,1,W265), ROUND(1440*SUM(MAP(Days,LAMBDA(d, IF(OR(WEEKDAY(d,2)=4,WEEKDAY(d,2)=5),0, MAX(0,MIN(EndDT,d+TIME(18,0,0))- MAX(StartDT,d+TIME(9,0,0))) ) ))),0) ))) | O265: =IF(M265="","", IF(M265="عدم پاسخ","بدون پاسخ", IF(L265="","اطلاعات ناقص", IF(L265<=DATA!$M$1,"رعایت شده","رعایت نشده")))) | W265: {=IF(D265="","",_xlfn.XLOOKUP(D265,DATA!B:B,DATA!L:L,""))} | X265: {=IF(F265="","",_xlfn.XLOOKUP(F265,DATA!B:B,DATA!L:L,""))}
C266: {=iferror(_xlfn.XLOOKUP(D266,DATA!B:B,DATA!A:A),"")} | H266: {=_xlfn.XLOOKUP(G266,DATA!D:D,DATA!E:E,"")} | L266: =IF(OR(W266="",X266="",J266="",K266="",M266<>"پاسخ داده شده"),"", IF(X266+K266<W266+J266,"خطای تاریخ", LET( StartDT,W266+J266, EndDT,X266+K266, Days,SEQUENCE(X266-W266+1,1,W266), ROUND(1440*SUM(MAP(Days,LAMBDA(d, IF(OR(WEEKDAY(d,2)=4,WEEKDAY(d,2)=5),0, MAX(0,MIN(EndDT,d+TIME(18,0,0))- MAX(StartDT,d+TIME(9,0,0))) ) ))),0) ))) | O266: =IF(M266="","", IF(M266="عدم پاسخ","بدون پاسخ", IF(L266="","اطلاعات ناقص", IF(L266<=DATA!$M$1,"رعایت شده","رعایت نشده")))) | W266: {=IF(D266="","",_xlfn.XLOOKUP(D266,DATA!B:B,DATA!L:L,""))} | X266: {=IF(F266="","",_xlfn.XLOOKUP(F266,DATA!B:B,DATA!L:L,""))}
C267: {=iferror(_xlfn.XLOOKUP(D267,DATA!B:B,DATA!A:A),"")} | H267: {=_xlfn.XLOOKUP(G267,DATA!D:D,DATA!E:E,"")} | L267: =IF(OR(W267="",X267="",J267="",K267="",M267<>"پاسخ داده شده"),"", IF(X267+K267<W267+J267,"خطای تاریخ", LET( StartDT,W267+J267, EndDT,X267+K267, Days,SEQUENCE(X267-W267+1,1,W267), ROUND(1440*SUM(MAP(Days,LAMBDA(d, IF(OR(WEEKDAY(d,2)=4,WEEKDAY(d,2)=5),0, MAX(0,MIN(EndDT,d+TIME(18,0,0))- MAX(StartDT,d+TIME(9,0,0))) ) ))),0) ))) | O267: =IF(M267="","", IF(M267="عدم پاسخ","بدون پاسخ", IF(L267="","اطلاعات ناقص", IF(L267<=DATA!$M$1,"رعایت شده","رعایت نشده")))) | W267: {=IF(D267="","",_xlfn.XLOOKUP(D267,DATA!B:B,DATA!L:L,""))} | X267: {=IF(F267="","",_xlfn.XLOOKUP(F267,DATA!B:B,DATA!L:L,""))}
C268: {=iferror(_xlfn.XLOOKUP(D268,DATA!B:B,DATA!A:A),"")} | H268: {=_xlfn.XLOOKUP(G268,DATA!D:D,DATA!E:E,"")} | L268: =IF(OR(W268="",X268="",J268="",K268="",M268<>"پاسخ داده شده"),"", IF(X268+K268<W268+J268,"خطای تاریخ", LET( StartDT,W268+J268, EndDT,X268+K268, Days,SEQUENCE(X268-W268+1,1,W268), ROUND(1440*SUM(MAP(Days,LAMBDA(d, IF(OR(WEEKDAY(d,2)=4,WEEKDAY(d,2)=5),0, MAX(0,MIN(EndDT,d+TIME(18,0,0))- MAX(StartDT,d+TIME(9,0,0))) ) ))),0) ))) | O268: =IF(M268="","", IF(M268="عدم پاسخ","بدون پاسخ", IF(L268="","اطلاعات ناقص", IF(L268<=DATA!$M$1,"رعایت شده","رعایت نشده")))) | W268: {=IF(D268="","",_xlfn.XLOOKUP(D268,DATA!B:B,DATA!L:L,""))} | X268: {=IF(F268="","",_xlfn.XLOOKUP(F268,DATA!B:B,DATA!L:L,""))}
C269: {=iferror(_xlfn.XLOOKUP(D269,DATA!B:B,DATA!A:A),"")} | H269: {=_xlfn.XLOOKUP(G269,DATA!D:D,DATA!E:E,"")} | L269: =IF(OR(W269="",X269="",J269="",K269="",M269<>"پاسخ داده شده"),"", IF(X269+K269<W269+J269,"خطای تاریخ", LET( StartDT,W269+J269, EndDT,X269+K269, Days,SEQUENCE(X269-W269+1,1,W269), ROUND(1440*SUM(MAP(Days,LAMBDA(d, IF(OR(WEEKDAY(d,2)=4,WEEKDAY(d,2)=5),0, MAX(0,MIN(EndDT,d+TIME(18,0,0))- MAX(StartDT,d+TIME(9,0,0))) ) ))),0) ))) | O269: =IF(M269="","", IF(M269="عدم پاسخ","بدون پاسخ", IF(L269="","اطلاعات ناقص", IF(L269<=DATA!$M$1,"رعایت شده","رعایت نشده")))) | W269: {=IF(D269="","",_xlfn.XLOOKUP(D269,DATA!B:B,DATA!L:L,""))} | X269: {=IF(F269="","",_xlfn.XLOOKUP(F269,DATA!B:B,DATA!L:L,""))}
C270: {=iferror(_xlfn.XLOOKUP(D270,DATA!B:B,DATA!A:A),"")} | H270: {=_xlfn.XLOOKUP(G270,DATA!D:D,DATA!E:E,"")} | L270: =IF(OR(W270="",X270="",J270="",K270="",M270<>"پاسخ داده شده"),"", IF(X270+K270<W270+J270,"خطای تاریخ", LET( StartDT,W270+J270, EndDT,X270+K270, Days,SEQUENCE(X270-W270+1,1,W270), ROUND(1440*SUM(MAP(Days,LAMBDA(d, IF(OR(WEEKDAY(d,2)=4,WEEKDAY(d,2)=5),0, MAX(0,MIN(EndDT,d+TIME(18,0,0))- MAX(StartDT,d+TIME(9,0,0))) ) ))),0) ))) | O270: =IF(M270="","", IF(M270="عدم پاسخ","بدون پاسخ", IF(L270="","اطلاعات ناقص", IF(L270<=DATA!$M$1,"رعایت شده","رعایت نشده")))) | W270: {=IF(D270="","",_xlfn.XLOOKUP(D270,DATA!B:B,DATA!L:L,""))} | X270: {=IF(F270="","",_xlfn.XLOOKUP(F270,DATA!B:B,DATA!L:L,""))}
C271: {=iferror(_xlfn.XLOOKUP(D271,DATA!B:B,DATA!A:A),"")} | H271: {=_xlfn.XLOOKUP(G271,DATA!D:D,DATA!E:E,"")} | L271: =IF(OR(W271="",X271="",J271="",K271="",M271<>"پاسخ داده شده"),"", IF(X271+K271<W271+J271,"خطای تاریخ", LET( StartDT,W271+J271, EndDT,X271+K271, Days,SEQUENCE(X271-W271+1,1,W271), ROUND(1440*SUM(MAP(Days,LAMBDA(d, IF(OR(WEEKDAY(d,2)=4,WEEKDAY(d,2)=5),0, MAX(0,MIN(EndDT,d+TIME(18,0,0))- MAX(StartDT,d+TIME(9,0,0))) ) ))),0) ))) | O271: =IF(M271="","", IF(M271="عدم پاسخ","بدون پاسخ", IF(L271="","اطلاعات ناقص", IF(L271<=DATA!$M$1,"رعایت شده","رعایت نشده")))) | W271: {=IF(D271="","",_xlfn.XLOOKUP(D271,DATA!B:B,DATA!L:L,""))} | X271: {=IF(F271="","",_xlfn.XLOOKUP(F271,DATA!B:B,DATA!L:L,""))}
... C544: {=iferror(_xlfn.XLOOKUP(D544,DATA!B:B,DATA!A:A),"")} | H544: {=_xlfn.XLOOKUP(G544,DATA!D:D,DATA!E:E,"")} | L544: =IF(OR(W544="",X544="",J544="",K544="",M544<>"پاسخ داده شده"),"", IF(X544+K544<W544+J544,"خطای تاریخ", LET( StartDT,W544+J544, EndDT,X544+K544, Days,SEQUENCE(X544-W544+1,1,W544), ROUND(1440*SUM(MAP(Days,LAMBDA(d, IF(OR(WEEKDAY(d,2)=4,WEEKDAY(d,2)=5),0, MAX(0,MIN(EndDT,d+TIME(18,0,0))- MAX(StartDT,d+TIME(9,0,0))) ) ))),0) ))) | O544: =IF(M544="","", IF(M544="عدم پاسخ","بدون پاسخ", IF(L544="","اطلاعات ناقص", IF(L544<=DATA!$M$1,"رعایت شده","رعایت نشده")))) | W544: {=IF(D544="","",_xlfn.XLOOKUP(D544,DATA!B:B,DATA!L:L,""))} | X544: {=IF(F544="","",_xlfn.XLOOKUP(F544,DATA!B:B,DATA!L:L,""))}
H545: {=_xlfn.XLOOKUP(G545,DATA!D:D,DATA!E:E,"")} | L545: =IF(OR(W545="",X545="",J545="",K545="",M545<>"پاسخ داده شده"),"", IF(X545+K545<W545+J545,"خطای تاریخ", LET( StartDT,W545+J545, EndDT,X545+K545, Days,SEQUENCE(X545-W545+1,1,W545), ROUND(1440*SUM(MAP(Days,LAMBDA(d, IF(OR(WEEKDAY(d,2)=4,WEEKDAY(d,2)=5),0, MAX(0,MIN(EndDT,d+TIME(18,0,0))- MAX(StartDT,d+TIME(9,0,0))) ) ))),0) ))) | O545: =IF(M545="","", IF(M545="عدم پاسخ","بدون پاسخ", IF(L545="","اطلاعات ناقص", IF(L545<=DATA!$M$1,"رعایت شده","رعایت نشده")))) | W545: {=IF(D545="","",_xlfn.XLOOKUP(D545,DATA!B:B,DATA!L:L,""))} | X545: {=IF(F545="","",_xlfn.XLOOKUP(F545,DATA!B:B,DATA!L:L,""))}
H546: {=_xlfn.XLOOKUP(G546,DATA!D:D,DATA!E:E,"")} | L546: =IF(OR(W546="",X546="",J546="",K546="",M546<>"پاسخ داده شده"),"", IF(X546+K546<W546+J546,"خطای تاریخ", LET( StartDT,W546+J546, EndDT,X546+K546, Days,SEQUENCE(X546-W546+1,1,W546), ROUND(1440*SUM(MAP(Days,LAMBDA(d, IF(OR(WEEKDAY(d,2)=4,WEEKDAY(d,2)=5),0, MAX(0,MIN(EndDT,d+TIME(18,0,0))- MAX(StartDT,d+TIME(9,0,0))) ) ))),0) ))) | O546: =IF(M546="","", IF(M546="عدم پاسخ","بدون پاسخ", IF(L546="","اطلاعات ناقص", IF(L546<=DATA!$M$1,"رعایت شده","رعایت نشده")))) | W546: {=IF(D546="","",_xlfn.XLOOKUP(D546,DATA!B:B,DATA!L:L,""))} | X546: {=IF(F546="","",_xlfn.XLOOKUP(F546,DATA!B:B,DATA!L:L,""))}
H547: {=_xlfn.XLOOKUP(G547,DATA!D:D,DATA!E:E,"")} | L547: =IF(OR(W547="",X547="",J547="",K547="",M547<>"پاسخ داده شده"),"", IF(X547+K547<W547+J547,"خطای تاریخ", LET( StartDT,W547+J547, EndDT,X547+K547, Days,SEQUENCE(X547-W547+1,1,W547), ROUND(1440*SUM(MAP(Days,LAMBDA(d, IF(OR(WEEKDAY(d,2)=4,WEEKDAY(d,2)=5),0, MAX(0,MIN(EndDT,d+TIME(18,0,0))- MAX(StartDT,d+TIME(9,0,0))) ) ))),0) ))) | O547: =IF(M547="","", IF(M547="عدم پاسخ","بدون پاسخ", IF(L547="","اطلاعات ناقص", IF(L547<=DATA!$M$1,"رعایت شده","رعایت نشده")))) | W547: {=IF(D547="","",_xlfn.XLOOKUP(D547,DATA!B:B,DATA!L:L,""))} | X547: {=IF(F547="","",_xlfn.XLOOKUP(F547,DATA!B:B,DATA!L:L,""))}
H548: {=_xlfn.XLOOKUP(G548,DATA!D:D,DATA!E:E,"")} | L548: =IF(OR(W548="",X548="",J548="",K548="",M548<>"پاسخ داده شده"),"", IF(X548+K548<W548+J548,"خطای تاریخ", LET( StartDT,W548+J548, EndDT,X548+K548, Days,SEQUENCE(X548-W548+1,1,W548), ROUND(1440*SUM(MAP(Days,LAMBDA(d, IF(OR(WEEKDAY(d,2)=4,WEEKDAY(d,2)=5),0, MAX(0,MIN(EndDT,d+TIME(18,0,0))- MAX(StartDT,d+TIME(9,0,0))) ) ))),0) ))) | O548: =IF(M548="","", IF(M548="عدم پاسخ","بدون پاسخ", IF(L548="","اطلاعات ناقص", IF(L548<=DATA!$M$1,"رعایت شده","رعایت نشده")))) | W548: {=IF(D548="","",_xlfn.XLOOKUP(D548,DATA!B:B,DATA!L:L,""))} | X548: {=IF(F548="","",_xlfn.XLOOKUP(F548,DATA!B:B,DATA!L:L,""))}
H549: {=_xlfn.XLOOKUP(G549,DATA!D:D,DATA!E:E,"")} | L549: =IF(OR(W549="",X549="",J549="",K549="",M549<>"پاسخ داده شده"),"", IF(X549+K549<W549+J549,"خطای تاریخ", LET( StartDT,W549+J549, EndDT,X549+K549, Days,SEQUENCE(X549-W549+1,1,W549), ROUND(1440*SUM(MAP(Days,LAMBDA(d, IF(OR(WEEKDAY(d,2)=4,WEEKDAY(d,2)=5),0, MAX(0,MIN(EndDT,d+TIME(18,0,0))- MAX(StartDT,d+TIME(9,0,0))) ) ))),0) ))) | O549: =IF(M549="","", IF(M549="عدم پاسخ","بدون پاسخ", IF(L549="","اطلاعات ناقص", IF(L549<=DATA!$M$1,"رعایت شده","رعایت نشده")))) | W549: {=IF(D549="","",_xlfn.XLOOKUP(D549,DATA!B:B,DATA!L:L,""))} | X549: {=IF(F549="","",_xlfn.XLOOKUP(F549,DATA!B:B,DATA!L:L,""))}
H550: {=_xlfn.XLOOKUP(G550,DATA!D:D,DATA!E:E,"")} | L550: =IF(OR(W550="",X550="",J550="",K550="",M550<>"پاسخ داده شده"),"", IF(X550+K550<W550+J550,"خطای تاریخ", LET( StartDT,W550+J550, EndDT,X550+K550, Days,SEQUENCE(X550-W550+1,1,W550), ROUND(1440*SUM(MAP(Days,LAMBDA(d, IF(OR(WEEKDAY(d,2)=4,WEEKDAY(d,2)=5),0, MAX(0,MIN(EndDT,d+TIME(18,0,0))- MAX(StartDT,d+TIME(9,0,0))) ) ))),0) ))) | O550: =IF(M550="","", IF(M550="عدم پاسخ","بدون پاسخ", IF(L550="","اطلاعات ناقص", IF(L550<=DATA!$M$1,"رعایت شده","رعایت نشده")))) | W550: {=IF(D550="","",_xlfn.XLOOKUP(D550,DATA!B:B,DATA!L:L,""))} | X550: {=IF(F550="","",_xlfn.XLOOKUP(F550,DATA!B:B,DATA!L:L,""))}
H551: {=_xlfn.XLOOKUP(G551,DATA!D:D,DATA!E:E,"")} | L551: =IF(OR(W551="",X551="",J551="",K551="",M551<>"پاسخ داده شده"),"", IF(X551+K551<W551+J551,"خطای تاریخ", LET( StartDT,W551+J551, EndDT,X551+K551, Days,SEQUENCE(X551-W551+1,1,W551), ROUND(1440*SUM(MAP(Days,LAMBDA(d, IF(OR(WEEKDAY(d,2)=4,WEEKDAY(d,2)=5),0, MAX(0,MIN(EndDT,d+TIME(18,0,0))- MAX(StartDT,d+TIME(9,0,0))) ) ))),0) ))) | O551: =IF(M551="","", IF(M551="عدم پاسخ","بدون پاسخ", IF(L551="","اطلاعات ناقص", IF(L551<=DATA!$M$1,"رعایت شده","رعایت نشده")))) | W551: {=IF(D551="","",_xlfn.XLOOKUP(D551,DATA!B:B,DATA!L:L,""))} | X551: {=IF(F551="","",_xlfn.XLOOKUP(F551,DATA!B:B,DATA!L:L,""))}
H552: {=_xlfn.XLOOKUP(G552,DATA!D:D,DATA!E:E,"")} | L552: =IF(OR(W552="",X552="",J552="",K552="",M552<>"پاسخ داده شده"),"", IF(X552+K552<W552+J552,"خطای تاریخ", LET( StartDT,W552+J552, EndDT,X552+K552, Days,SEQUENCE(X552-W552+1,1,W552), ROUND(1440*SUM(MAP(Days,LAMBDA(d, IF(OR(WEEKDAY(d,2)=4,WEEKDAY(d,2)=5),0, MAX(0,MIN(EndDT,d+TIME(18,0,0))- MAX(StartDT,d+TIME(9,0,0))) ) ))),0) ))) | O552: =IF(M552="","", IF(M552="عدم پاسخ","بدون پاسخ", IF(L552="","اطلاعات ناقص", IF(L552<=DATA!$M$1,"رعایت شده","رعایت نشده")))) | W552: {=IF(D552="","",_xlfn.XLOOKUP(D552,DATA!B:B,DATA!L:L,""))} | X552: {=IF(F552="","",_xlfn.XLOOKUP(F552,DATA!B:B,DATA!L:L,""))}
H553: {=_xlfn.XLOOKUP(G553,DATA!D:D,DATA!E:E,"")} | L553: =IF(OR(W553="",X553="",J553="",K553="",M553<>"پاسخ داده شده"),"", IF(X553+K553<W553+J553,"خطای تاریخ", LET( StartDT,W553+J553, EndDT,X553+K553, Days,SEQUENCE(X553-W553+1,1,W553), ROUND(1440*SUM(MAP(Days,LAMBDA(d, IF(OR(WEEKDAY(d,2)=4,WEEKDAY(d,2)=5),0, MAX(0,MIN(EndDT,d+TIME(18,0,0))- MAX(StartDT,d+TIME(9,0,0))) ) ))),0) ))) | O553: =IF(M553="","", IF(M553="عدم پاسخ","بدون پاسخ", IF(L553="","اطلاعات ناقص", IF(L553<=DATA!$M$1,"رعایت شده","رعایت نشده")))) | W553: {=IF(D553="","",_xlfn.XLOOKUP(D553,DATA!B:B,DATA!L:L,""))} | X553: {=IF(F553="","",_xlfn.XLOOKUP(F553,DATA!B:B,DATA!L:L,""))}
...

Sheet Agent Report
A1: نام کارشناس | B1: تیم | C1: تعداد ارزیابی نمره‌دار | D1: میانگین نمره نهایی / 100 | E1: تعداد پیام پاسخ‌داده‌شده | F1: درصد رعایت SLA واقعی | G1: میانگین المان SLA / 100 | H1: میانگین پیگیری / 100 | I1: میانگین پایان‌بندی / 100 | J1: میانگین لحن / 100 | K1: تعداد عدم پاسخ | L1: تعداد SLA رعایت‌نشده
B2: {=_xlfn.XLOOKUP(A2,DATA!D:D,DATA!E:E,"")} | C2: =IF($A2="","",COUNTIFS(Evaluations!$G$3:$G$10000,$A2,Evaluations!$U$3:$U$10000,">=0",Evaluations!$U$3:$U$10000,"<=100")) | D2: =IF(OR($A2="",C2=0),"",ROUND(SUMIFS(Evaluations!$U$3:$U$10000,Evaluations!$G$3:$G$10000,$A2)/C2,2)) | E2: =IF($A2="","",COUNTIFS(Evaluations!$G$3:$G$10000,$A2,Evaluations!$M$3:$M$10000,"پاسخ داده شده")) | F2: =IF($A2="","",IFERROR(COUNTIFS(Evaluations!$G$3:$G$10000,$A2,Evaluations!$O$3:$O$10000,"رعایت شده")/(COUNTIFS(Evaluations!$G$3:$G$10000,$A2,Evaluations!$O$3:$O$10000,"رعایت شده")+COUNTIFS(Evaluations!$G$3:$G$10000,$A2,Evaluations!$O$3:$O$10000,"رعایت نشده")),"")) | G2: =IF($A2="","",IFERROR(ROUND(100*COUNTIFS(Evaluations!$G$3:$G$10000,$A2,Evaluations!$Q$3:$Q$10000,1)/(COUNTIFS(Evaluations!$G$3:$G$10000,$A2,Evaluations!$Q$3:$Q$10000,1)+COUNTIFS(Evaluations!$G$3:$G$10000,$A2,Evaluations!$Q$3:$Q$10000,0)),2),"")) | H2: =IF($A2="","",IFERROR(ROUND(100*COUNTIFS(Evaluations!$G$3:$G$10000,$A2,Evaluations!$R$3:$R$10000,1)/(COUNTIFS(Evaluations!$G$3:$G$10000,$A2,Evaluations!$R$3:$R$10000,1)+COUNTIFS(Evaluations!$G$3:$G$10000,$A2,Evaluations!$R$3:$R$10000,0)),2),"")) | I2: =IF($A2="","",IFERROR(ROUND(100*COUNTIFS(Evaluations!$G$3:$G$10000,$A2,Evaluations!$S$3:$S$10000,1)/(COUNTIFS(Evaluations!$G$3:$G$10000,$A2,Evaluations!$S$3:$S$10000,1)+COUNTIFS(Evaluations!$G$3:$G$10000,$A2,Evaluations!$S$3:$S$10000,0)),2),"")) | J2: =IF($A2="","",IFERROR(ROUND(100*COUNTIFS(Evaluations!$G$3:$G$10000,$A2,Evaluations!$T$3:$T$10000,1)/(COUNTIFS(Evaluations!$G$3:$G$10000,$A2,Evaluations!$T$3:$T$10000,1)+COUNTIFS(Evaluations!$G$3:$G$10000,$A2,Evaluations!$T$3:$T$10000,0)),2),"")) | K2: =IF($A2="","",COUNTIFS(Evaluations!$G$3:$G$10000,$A2,Evaluations!$M$3:$M$10000,"عدم پاسخ")) | L2: =IF($A2="","",COUNTIFS(Evaluations!$G$3:$G$10000,$A2,Evaluations!$O$3:$O$10000,"رعایت نشده"))
B3: {=_xlfn.XLOOKUP(A3,DATA!D:D,DATA!E:E,"")} | C3: =IF($A3="","",COUNTIFS(Evaluations!$G$3:$G$10000,$A3,Evaluations!$U$3:$U$10000,">=0",Evaluations!$U$3:$U$10000,"<=100")) | D3: =IF(OR($A3="",C3=0),"",ROUND(SUMIFS(Evaluations!$U$3:$U$10000,Evaluations!$G$3:$G$10000,$A3)/C3,2)) | E3: =IF($A3="","",COUNTIFS(Evaluations!$G$3:$G$10000,$A3,Evaluations!$M$3:$M$10000,"پاسخ داده شده")) | F3: =IF($A3="","",IFERROR(COUNTIFS(Evaluations!$G$3:$G$10000,$A3,Evaluations!$O$3:$O$10000,"رعایت شده")/(COUNTIFS(Evaluations!$G$3:$G$10000,$A3,Evaluations!$O$3:$O$10000,"رعایت شده")+COUNTIFS(Evaluations!$G$3:$G$10000,$A3,Evaluations!$O$3:$O$10000,"رعایت نشده")),"")) | G3: =IF($A3="","",IFERROR(ROUND(100*COUNTIFS(Evaluations!$G$3:$G$10000,$A3,Evaluations!$Q$3:$Q$10000,1)/(COUNTIFS(Evaluations!$G$3:$G$10000,$A3,Evaluations!$Q$3:$Q$10000,1)+COUNTIFS(Evaluations!$G$3:$G$10000,$A3,Evaluations!$Q$3:$Q$10000,0)),2),"")) | H3: =IF($A3="","",IFERROR(ROUND(100*COUNTIFS(Evaluations!$G$3:$G$10000,$A3,Evaluations!$R$3:$R$10000,1)/(COUNTIFS(Evaluations!$G$3:$G$10000,$A3,Evaluations!$R$3:$R$10000,1)+COUNTIFS(Evaluations!$G$3:$G$10000,$A3,Evaluations!$R$3:$R$10000,0)),2),"")) | I3: =IF($A3="","",IFERROR(ROUND(100*COUNTIFS(Evaluations!$G$3:$G$10000,$A3,Evaluations!$S$3:$S$10000,1)/(COUNTIFS(Evaluations!$G$3:$G$10000,$A3,Evaluations!$S$3:$S$10000,1)+COUNTIFS(Evaluations!$G$3:$G$10000,$A3,Evaluations!$S$3:$S$10000,0)),2),"")) | J3: =IF($A3="","",IFERROR(ROUND(100*COUNTIFS(Evaluations!$G$3:$G$10000,$A3,Evaluations!$T$3:$T$10000,1)/(COUNTIFS(Evaluations!$G$3:$G$10000,$A3,Evaluations!$T$3:$T$10000,1)+COUNTIFS(Evaluations!$G$3:$G$10000,$A3,Evaluations!$T$3:$T$10000,0)),2),"")) | K3: =IF($A3="","",COUNTIFS(Evaluations!$G$3:$G$10000,$A3,Evaluations!$M$3:$M$10000,"عدم پاسخ")) | L3: =IF($A3="","",COUNTIFS(Evaluations!$G$3:$G$10000,$A3,Evaluations!$O$3:$O$10000,"رعایت نشده"))
B4: {=_xlfn.XLOOKUP(A4,DATA!D:D,DATA!E:E,"")} | C4: =IF($A4="","",COUNTIFS(Evaluations!$G$3:$G$10000,$A4,Evaluations!$U$3:$U$10000,">=0",Evaluations!$U$3:$U$10000,"<=100")) | D4: =IF(OR($A4="",C4=0),"",ROUND(SUMIFS(Evaluations!$U$3:$U$10000,Evaluations!$G$3:$G$10000,$A4)/C4,2)) | E4: =IF($A4="","",COUNTIFS(Evaluations!$G$3:$G$10000,$A4,Evaluations!$M$3:$M$10000,"پاسخ داده شده")) | F4: =IF($A4="","",IFERROR(COUNTIFS(Evaluations!$G$3:$G$10000,$A4,Evaluations!$O$3:$O$10000,"رعایت شده")/(COUNTIFS(Evaluations!$G$3:$G$10000,$A4,Evaluations!$O$3:$O$10000,"رعایت شده")+COUNTIFS(Evaluations!$G$3:$G$10000,$A4,Evaluations!$O$3:$O$10000,"رعایت نشده")),"")) | G4: =IF($A4="","",IFERROR(ROUND(100*COUNTIFS(Evaluations!$G$3:$G$10000,$A4,Evaluations!$Q$3:$Q$10000,1)/(COUNTIFS(Evaluations!$G$3:$G$10000,$A4,Evaluations!$Q$3:$Q$10000,1)+COUNTIFS(Evaluations!$G$3:$G$10000,$A4,Evaluations!$Q$3:$Q$10000,0)),2),"")) | H4: =IF($A4="","",IFERROR(ROUND(100*COUNTIFS(Evaluations!$G$3:$G$10000,$A4,Evaluations!$R$3:$R$10000,1)/(COUNTIFS(Evaluations!$G$3:$G$10000,$A4,Evaluations!$R$3:$R$10000,1)+COUNTIFS(Evaluations!$G$3:$G$10000,$A4,Evaluations!$R$3:$R$10000,0)),2),"")) | I4: =IF($A4="","",IFERROR(ROUND(100*COUNTIFS(Evaluations!$G$3:$G$10000,$A4,Evaluations!$S$3:$S$10000,1)/(COUNTIFS(Evaluations!$G$3:$G$10000,$A4,Evaluations!$S$3:$S$10000,1)+COUNTIFS(Evaluations!$G$3:$G$10000,$A4,Evaluations!$S$3:$S$10000,0)),2),"")) | J4: =IF($A4="","",IFERROR(ROUND(100*COUNTIFS(Evaluations!$G$3:$G$10000,$A4,Evaluations!$T$3:$T$10000,1)/(COUNTIFS(Evaluations!$G$3:$G$10000,$A4,Evaluations!$T$3:$T$10000,1)+COUNTIFS(Evaluations!$G$3:$G$10000,$A4,Evaluations!$T$3:$T$10000,0)),2),"")) | K4: =IF($A4="","",COUNTIFS(Evaluations!$G$3:$G$10000,$A4,Evaluations!$M$3:$M$10000,"عدم پاسخ")) | L4: =IF($A4="","",COUNTIFS(Evaluations!$G$3:$G$10000,$A4,Evaluations!$O$3:$O$10000,"رعایت نشده"))
B5: {=_xlfn.XLOOKUP(A5,DATA!D:D,DATA!E:E,"")} | C5: =IF($A5="","",COUNTIFS(Evaluations!$G$3:$G$10000,$A5,Evaluations!$U$3:$U$10000,">=0",Evaluations!$U$3:$U$10000,"<=100")) | D5: =IF(OR($A5="",C5=0),"",ROUND(SUMIFS(Evaluations!$U$3:$U$10000,Evaluations!$G$3:$G$10000,$A5)/C5,2)) | E5: =IF($A5="","",COUNTIFS(Evaluations!$G$3:$G$10000,$A5,Evaluations!$M$3:$M$10000,"پاسخ داده شده")) | F5: =IF($A5="","",IFERROR(COUNTIFS(Evaluations!$G$3:$G$10000,$A5,Evaluations!$O$3:$O$10000,"رعایت شده")/(COUNTIFS(Evaluations!$G$3:$G$10000,$A5,Evaluations!$O$3:$O$10000,"رعایت شده")+COUNTIFS(Evaluations!$G$3:$G$10000,$A5,Evaluations!$O$3:$O$10000,"رعایت نشده")),"")) | G5: =IF($A5="","",IFERROR(ROUND(100*COUNTIFS(Evaluations!$G$3:$G$10000,$A5,Evaluations!$Q$3:$Q$10000,1)/(COUNTIFS(Evaluations!$G$3:$G$10000,$A5,Evaluations!$Q$3:$Q$10000,1)+COUNTIFS(Evaluations!$G$3:$G$10000,$A5,Evaluations!$Q$3:$Q$10000,0)),2),"")) | H5: =IF($A5="","",IFERROR(ROUND(100*COUNTIFS(Evaluations!$G$3:$G$10000,$A5,Evaluations!$R$3:$R$10000,1)/(COUNTIFS(Evaluations!$G$3:$G$10000,$A5,Evaluations!$R$3:$R$10000,1)+COUNTIFS(Evaluations!$G$3:$G$10000,$A5,Evaluations!$R$3:$R$10000,0)),2),"")) | I5: =IF($A5="","",IFERROR(ROUND(100*COUNTIFS(Evaluations!$G$3:$G$10000,$A5,Evaluations!$S$3:$S$10000,1)/(COUNTIFS(Evaluations!$G$3:$G$10000,$A5,Evaluations!$S$3:$S$10000,1)+COUNTIFS(Evaluations!$G$3:$G$10000,$A5,Evaluations!$S$3:$S$10000,0)),2),"")) | J5: =IF($A5="","",IFERROR(ROUND(100*COUNTIFS(Evaluations!$G$3:$G$10000,$A5,Evaluations!$T$3:$T$10000,1)/(COUNTIFS(Evaluations!$G$3:$G$10000,$A5,Evaluations!$T$3:$T$10000,1)+COUNTIFS(Evaluations!$G$3:$G$10000,$A5,Evaluations!$T$3:$T$10000,0)),2),"")) | K5: =IF($A5="","",COUNTIFS(Evaluations!$G$3:$G$10000,$A5,Evaluations!$M$3:$M$10000,"عدم پاسخ")) | L5: =IF($A5="","",COUNTIFS(Evaluations!$G$3:$G$10000,$A5,Evaluations!$O$3:$O$10000,"رعایت نشده"))
B6: {=_xlfn.XLOOKUP(A6,DATA!D:D,DATA!E:E,"")} | C6: =IF($A6="","",COUNTIFS(Evaluations!$G$3:$G$10000,$A6,Evaluations!$U$3:$U$10000,">=0",Evaluations!$U$3:$U$10000,"<=100")) | D6: =IF(OR($A6="",C6=0),"",ROUND(SUMIFS(Evaluations!$U$3:$U$10000,Evaluations!$G$3:$G$10000,$A6)/C6,2)) | E6: =IF($A6="","",COUNTIFS(Evaluations!$G$3:$G$10000,$A6,Evaluations!$M$3:$M$10000,"پاسخ داده شده")) | F6: =IF($A6="","",IFERROR(COUNTIFS(Evaluations!$G$3:$G$10000,$A6,Evaluations!$O$3:$O$10000,"رعایت شده")/(COUNTIFS(Evaluations!$G$3:$G$10000,$A6,Evaluations!$O$3:$O$10000,"رعایت شده")+COUNTIFS(Evaluations!$G$3:$G$10000,$A6,Evaluations!$O$3:$O$10000,"رعایت نشده")),"")) | G6: =IF($A6="","",IFERROR(ROUND(100*COUNTIFS(Evaluations!$G$3:$G$10000,$A6,Evaluations!$Q$3:$Q$10000,1)/(COUNTIFS(Evaluations!$G$3:$G$10000,$A6,Evaluations!$Q$3:$Q$10000,1)+COUNTIFS(Evaluations!$G$3:$G$10000,$A6,Evaluations!$Q$3:$Q$10000,0)),2),"")) | H6: =IF($A6="","",IFERROR(ROUND(100*COUNTIFS(Evaluations!$G$3:$G$10000,$A6,Evaluations!$R$3:$R$10000,1)/(COUNTIFS(Evaluations!$G$3:$G$10000,$A6,Evaluations!$R$3:$R$10000,1)+COUNTIFS(Evaluations!$G$3:$G$10000,$A6,Evaluations!$R$3:$R$10000,0)),2),"")) | I6: =IF($A6="","",IFERROR(ROUND(100*COUNTIFS(Evaluations!$G$3:$G$10000,$A6,Evaluations!$S$3:$S$10000,1)/(COUNTIFS(Evaluations!$G$3:$G$10000,$A6,Evaluations!$S$3:$S$10000,1)+COUNTIFS(Evaluations!$G$3:$G$10000,$A6,Evaluations!$S$3:$S$10000,0)),2),"")) | J6: =IF($A6="","",IFERROR(ROUND(100*COUNTIFS(Evaluations!$G$3:$G$10000,$A6,Evaluations!$T$3:$T$10000,1)/(COUNTIFS(Evaluations!$G$3:$G$10000,$A6,Evaluations!$T$3:$T$10000,1)+COUNTIFS(Evaluations!$G$3:$G$10000,$A6,Evaluations!$T$3:$T$10000,0)),2),"")) | K6: =IF($A6="","",COUNTIFS(Evaluations!$G$3:$G$10000,$A6,Evaluations!$M$3:$M$10000,"عدم پاسخ")) | L6: =IF($A6="","",COUNTIFS(Evaluations!$G$3:$G$10000,$A6,Evaluations!$O$3:$O$10000,"رعایت نشده"))
B7: {=_xlfn.XLOOKUP(A7,DATA!D:D,DATA!E:E,"")} | C7: =IF($A7="","",COUNTIFS(Evaluations!$G$3:$G$10000,$A7,Evaluations!$U$3:$U$10000,">=0",Evaluations!$U$3:$U$10000,"<=100")) | D7: =IF(OR($A7="",C7=0),"",ROUND(SUMIFS(Evaluations!$U$3:$U$10000,Evaluations!$G$3:$G$10000,$A7)/C7,2)) | E7: =IF($A7="","",COUNTIFS(Evaluations!$G$3:$G$10000,$A7,Evaluations!$M$3:$M$10000,"پاسخ داده شده")) | F7: =IF($A7="","",IFERROR(COUNTIFS(Evaluations!$G$3:$G$10000,$A7,Evaluations!$O$3:$O$10000,"رعایت شده")/(COUNTIFS(Evaluations!$G$3:$G$10000,$A7,Evaluations!$O$3:$O$10000,"رعایت شده")+COUNTIFS(Evaluations!$G$3:$G$10000,$A7,Evaluations!$O$3:$O$10000,"رعایت نشده")),"")) | G7: =IF($A7="","",IFERROR(ROUND(100*COUNTIFS(Evaluations!$G$3:$G$10000,$A7,Evaluations!$Q$3:$Q$10000,1)/(COUNTIFS(Evaluations!$G$3:$G$10000,$A7,Evaluations!$Q$3:$Q$10000,1)+COUNTIFS(Evaluations!$G$3:$G$10000,$A7,Evaluations!$Q$3:$Q$10000,0)),2),"")) | H7: =IF($A7="","",IFERROR(ROUND(100*COUNTIFS(Evaluations!$G$3:$G$10000,$A7,Evaluations!$R$3:$R$10000,1)/(COUNTIFS(Evaluations!$G$3:$G$10000,$A7,Evaluations!$R$3:$R$10000,1)+COUNTIFS(Evaluations!$G$3:$G$10000,$A7,Evaluations!$R$3:$R$10000,0)),2),"")) | I7: =IF($A7="","",IFERROR(ROUND(100*COUNTIFS(Evaluations!$G$3:$G$10000,$A7,Evaluations!$S$3:$S$10000,1)/(COUNTIFS(Evaluations!$G$3:$G$10000,$A7,Evaluations!$S$3:$S$10000,1)+COUNTIFS(Evaluations!$G$3:$G$10000,$A7,Evaluations!$S$3:$S$10000,0)),2),"")) | J7: =IF($A7="","",IFERROR(ROUND(100*COUNTIFS(Evaluations!$G$3:$G$10000,$A7,Evaluations!$T$3:$T$10000,1)/(COUNTIFS(Evaluations!$G$3:$G$10000,$A7,Evaluations!$T$3:$T$10000,1)+COUNTIFS(Evaluations!$G$3:$G$10000,$A7,Evaluations!$T$3:$T$10000,0)),2),"")) | K7: =IF($A7="","",COUNTIFS(Evaluations!$G$3:$G$10000,$A7,Evaluations!$M$3:$M$10000,"عدم پاسخ")) | L7: =IF($A7="","",COUNTIFS(Evaluations!$G$3:$G$10000,$A7,Evaluations!$O$3:$O$10000,"رعایت نشده"))
B8: {=_xlfn.XLOOKUP(A8,DATA!D:D,DATA!E:E,"")} | C8: =IF($A8="","",COUNTIFS(Evaluations!$G$3:$G$10000,$A8,Evaluations!$U$3:$U$10000,">=0",Evaluations!$U$3:$U$10000,"<=100")) | D8: =IF(OR($A8="",C8=0),"",ROUND(SUMIFS(Evaluations!$U$3:$U$10000,Evaluations!$G$3:$G$10000,$A8)/C8,2)) | E8: =IF($A8="","",COUNTIFS(Evaluations!$G$3:$G$10000,$A8,Evaluations!$M$3:$M$10000,"پاسخ داده شده")) | F8: =IF($A8="","",IFERROR(COUNTIFS(Evaluations!$G$3:$G$10000,$A8,Evaluations!$O$3:$O$10000,"رعایت شده")/(COUNTIFS(Evaluations!$G$3:$G$10000,$A8,Evaluations!$O$3:$O$10000,"رعایت شده")+COUNTIFS(Evaluations!$G$3:$G$10000,$A8,Evaluations!$O$3:$O$10000,"رعایت نشده")),"")) | G8: =IF($A8="","",IFERROR(ROUND(100*COUNTIFS(Evaluations!$G$3:$G$10000,$A8,Evaluations!$Q$3:$Q$10000,1)/(COUNTIFS(Evaluations!$G$3:$G$10000,$A8,Evaluations!$Q$3:$Q$10000,1)+COUNTIFS(Evaluations!$G$3:$G$10000,$A8,Evaluations!$Q$3:$Q$10000,0)),2),"")) | H8: =IF($A8="","",IFERROR(ROUND(100*COUNTIFS(Evaluations!$G$3:$G$10000,$A8,Evaluations!$R$3:$R$10000,1)/(COUNTIFS(Evaluations!$G$3:$G$10000,$A8,Evaluations!$R$3:$R$10000,1)+COUNTIFS(Evaluations!$G$3:$G$10000,$A8,Evaluations!$R$3:$R$10000,0)),2),"")) | I8: =IF($A8="","",IFERROR(ROUND(100*COUNTIFS(Evaluations!$G$3:$G$10000,$A8,Evaluations!$S$3:$S$10000,1)/(COUNTIFS(Evaluations!$G$3:$G$10000,$A8,Evaluations!$S$3:$S$10000,1)+COUNTIFS(Evaluations!$G$3:$G$10000,$A8,Evaluations!$S$3:$S$10000,0)),2),"")) | J8: =IF($A8="","",IFERROR(ROUND(100*COUNTIFS(Evaluations!$G$3:$G$10000,$A8,Evaluations!$T$3:$T$10000,1)/(COUNTIFS(Evaluations!$G$3:$G$10000,$A8,Evaluations!$T$3:$T$10000,1)+COUNTIFS(Evaluations!$G$3:$G$10000,$A8,Evaluations!$T$3:$T$10000,0)),2),"")) | K8: =IF($A8="","",COUNTIFS(Evaluations!$G$3:$G$10000,$A8,Evaluations!$M$3:$M$10000,"عدم پاسخ")) | L8: =IF($A8="","",COUNTIFS(Evaluations!$G$3:$G$10000,$A8,Evaluations!$O$3:$O$10000,"رعایت نشده"))
B9: {=_xlfn.XLOOKUP(A9,DATA!D:D,DATA!E:E,"")} | C9: =IF($A9="","",COUNTIFS(Evaluations!$G$3:$G$10000,$A9,Evaluations!$U$3:$U$10000,">=0",Evaluations!$U$3:$U$10000,"<=100")) | D9: =IF(OR($A9="",C9=0),"",ROUND(SUMIFS(Evaluations!$U$3:$U$10000,Evaluations!$G$3:$G$10000,$A9)/C9,2)) | E9: =IF($A9="","",COUNTIFS(Evaluations!$G$3:$G$10000,$A9,Evaluations!$M$3:$M$10000,"پاسخ داده شده")) | F9: =IF($A9="","",IFERROR(COUNTIFS(Evaluations!$G$3:$G$10000,$A9,Evaluations!$O$3:$O$10000,"رعایت شده")/(COUNTIFS(Evaluations!$G$3:$G$10000,$A9,Evaluations!$O$3:$O$10000,"رعایت شده")+COUNTIFS(Evaluations!$G$3:$G$10000,$A9,Evaluations!$O$3:$O$10000,"رعایت نشده")),"")) | G9: =IF($A9="","",IFERROR(ROUND(100*COUNTIFS(Evaluations!$G$3:$G$10000,$A9,Evaluations!$Q$3:$Q$10000,1)/(COUNTIFS(Evaluations!$G$3:$G$10000,$A9,Evaluations!$Q$3:$Q$10000,1)+COUNTIFS(Evaluations!$G$3:$G$10000,$A9,Evaluations!$Q$3:$Q$10000,0)),2),"")) | H9: =IF($A9="","",IFERROR(ROUND(100*COUNTIFS(Evaluations!$G$3:$G$10000,$A9,Evaluations!$R$3:$R$10000,1)/(COUNTIFS(Evaluations!$G$3:$G$10000,$A9,Evaluations!$R$3:$R$10000,1)+COUNTIFS(Evaluations!$G$3:$G$10000,$A9,Evaluations!$R$3:$R$10000,0)),2),"")) | I9: =IF($A9="","",IFERROR(ROUND(100*COUNTIFS(Evaluations!$G$3:$G$10000,$A9,Evaluations!$S$3:$S$10000,1)/(COUNTIFS(Evaluations!$G$3:$G$10000,$A9,Evaluations!$S$3:$S$10000,1)+COUNTIFS(Evaluations!$G$3:$G$10000,$A9,Evaluations!$S$3:$S$10000,0)),2),"")) | J9: =IF($A9="","",IFERROR(ROUND(100*COUNTIFS(Evaluations!$G$3:$G$10000,$A9,Evaluations!$T$3:$T$10000,1)/(COUNTIFS(Evaluations!$G$3:$G$10000,$A9,Evaluations!$T$3:$T$10000,1)+COUNTIFS(Evaluations!$G$3:$G$10000,$A9,Evaluations!$T$3:$T$10000,0)),2),"")) | K9: =IF($A9="","",COUNTIFS(Evaluations!$G$3:$G$10000,$A9,Evaluations!$M$3:$M$10000,"عدم پاسخ")) | L9: =IF($A9="","",COUNTIFS(Evaluations!$G$3:$G$10000,$A9,Evaluations!$O$3:$O$10000,"رعایت نشده"))
B10: {=_xlfn.XLOOKUP(A10,DATA!D:D,DATA!E:E,"")} | C10: =IF($A10="","",COUNTIFS(Evaluations!$G$3:$G$10000,$A10,Evaluations!$U$3:$U$10000,">=0",Evaluations!$U$3:$U$10000,"<=100")) | D10: =IF(OR($A10="",C10=0),"",ROUND(SUMIFS(Evaluations!$U$3:$U$10000,Evaluations!$G$3:$G$10000,$A10)/C10,2)) | E10: =IF($A10="","",COUNTIFS(Evaluations!$G$3:$G$10000,$A10,Evaluations!$M$3:$M$10000,"پاسخ داده شده")) | F10: =IF($A10="","",IFERROR(COUNTIFS(Evaluations!$G$3:$G$10000,$A10,Evaluations!$O$3:$O$10000,"رعایت شده")/(COUNTIFS(Evaluations!$G$3:$G$10000,$A10,Evaluations!$O$3:$O$10000,"رعایت شده")+COUNTIFS(Evaluations!$G$3:$G$10000,$A10,Evaluations!$O$3:$O$10000,"رعایت نشده")),"")) | G10: =IF($A10="","",IFERROR(ROUND(100*COUNTIFS(Evaluations!$G$3:$G$10000,$A10,Evaluations!$Q$3:$Q$10000,1)/(COUNTIFS(Evaluations!$G$3:$G$10000,$A10,Evaluations!$Q$3:$Q$10000,1)+COUNTIFS(Evaluations!$G$3:$G$10000,$A10,Evaluations!$Q$3:$Q$10000,0)),2),"")) | H10: =IF($A10="","",IFERROR(ROUND(100*COUNTIFS(Evaluations!$G$3:$G$10000,$A10,Evaluations!$R$3:$R$10000,1)/(COUNTIFS(Evaluations!$G$3:$G$10000,$A10,Evaluations!$R$3:$R$10000,1)+COUNTIFS(Evaluations!$G$3:$G$10000,$A10,Evaluations!$R$3:$R$10000,0)),2),"")) | I10: =IF($A10="","",IFERROR(ROUND(100*COUNTIFS(Evaluations!$G$3:$G$10000,$A10,Evaluations!$S$3:$S$10000,1)/(COUNTIFS(Evaluations!$G$3:$G$10000,$A10,Evaluations!$S$3:$S$10000,1)+COUNTIFS(Evaluations!$G$3:$G$10000,$A10,Evaluations!$S$3:$S$10000,0)),2),"")) | J10: =IF($A10="","",IFERROR(ROUND(100*COUNTIFS(Evaluations!$G$3:$G$10000,$A10,Evaluations!$T$3:$T$10000,1)/(COUNTIFS(Evaluations!$G$3:$G$10000,$A10,Evaluations!$T$3:$T$10000,1)+COUNTIFS(Evaluations!$G$3:$G$10000,$A10,Evaluations!$T$3:$T$10000,0)),2),"")) | K10: =IF($A10="","",COUNTIFS(Evaluations!$G$3:$G$10000,$A10,Evaluations!$M$3:$M$10000,"عدم پاسخ")) | L10: =IF($A10="","",COUNTIFS(Evaluations!$G$3:$G$10000,$A10,Evaluations!$O$3:$O$10000,"رعایت نشده"))
B11: {=_xlfn.XLOOKUP(A11,DATA!D:D,DATA!E:E,"")} | C11: =IF($A11="","",COUNTIFS(Evaluations!$G$3:$G$10000,$A11,Evaluations!$U$3:$U$10000,">=0",Evaluations!$U$3:$U$10000,"<=100")) | D11: =IF(OR($A11="",C11=0),"",ROUND(SUMIFS(Evaluations!$U$3:$U$10000,Evaluations!$G$3:$G$10000,$A11)/C11,2)) | E11: =IF($A11="","",COUNTIFS(Evaluations!$G$3:$G$10000,$A11,Evaluations!$M$3:$M$10000,"پاسخ داده شده")) | F11: =IF($A11="","",IFERROR(COUNTIFS(Evaluations!$G$3:$G$10000,$A11,Evaluations!$O$3:$O$10000,"رعایت شده")/(COUNTIFS(Evaluations!$G$3:$G$10000,$A11,Evaluations!$O$3:$O$10000,"رعایت شده")+COUNTIFS(Evaluations!$G$3:$G$10000,$A11,Evaluations!$O$3:$O$10000,"رعایت نشده")),"")) | G11: =IF($A11="","",IFERROR(ROUND(100*COUNTIFS(Evaluations!$G$3:$G$10000,$A11,Evaluations!$Q$3:$Q$10000,1)/(COUNTIFS(Evaluations!$G$3:$G$10000,$A11,Evaluations!$Q$3:$Q$10000,1)+COUNTIFS(Evaluations!$G$3:$G$10000,$A11,Evaluations!$Q$3:$Q$10000,0)),2),"")) | H11: =IF($A11="","",IFERROR(ROUND(100*COUNTIFS(Evaluations!$G$3:$G$10000,$A11,Evaluations!$R$3:$R$10000,1)/(COUNTIFS(Evaluations!$G$3:$G$10000,$A11,Evaluations!$R$3:$R$10000,1)+COUNTIFS(Evaluations!$G$3:$G$10000,$A11,Evaluations!$R$3:$R$10000,0)),2),"")) | I11: =IF($A11="","",IFERROR(ROUND(100*COUNTIFS(Evaluations!$G$3:$G$10000,$A11,Evaluations!$S$3:$S$10000,1)/(COUNTIFS(Evaluations!$G$3:$G$10000,$A11,Evaluations!$S$3:$S$10000,1)+COUNTIFS(Evaluations!$G$3:$G$10000,$A11,Evaluations!$S$3:$S$10000,0)),2),"")) | J11: =IF($A11="","",IFERROR(ROUND(100*COUNTIFS(Evaluations!$G$3:$G$10000,$A11,Evaluations!$T$3:$T$10000,1)/(COUNTIFS(Evaluations!$G$3:$G$10000,$A11,Evaluations!$T$3:$T$10000,1)+COUNTIFS(Evaluations!$G$3:$G$10000,$A11,Evaluations!$T$3:$T$10000,0)),2),"")) | K11: =IF($A11="","",COUNTIFS(Evaluations!$G$3:$G$10000,$A11,Evaluations!$M$3:$M$10000,"عدم پاسخ")) | L11: =IF($A11="","",COUNTIFS(Evaluations!$G$3:$G$10000,$A11,Evaluations!$O$3:$O$10000,"رعایت نشده"))
B12: {=_xlfn.XLOOKUP(A12,DATA!D:D,DATA!E:E,"")} | C12: =IF($A12="","",COUNTIFS(Evaluations!$G$3:$G$10000,$A12,Evaluations!$U$3:$U$10000,">=0",Evaluations!$U$3:$U$10000,"<=100")) | D12: =IF(OR($A12="",C12=0),"",ROUND(SUMIFS(Evaluations!$U$3:$U$10000,Evaluations!$G$3:$G$10000,$A12)/C12,2)) | E12: =IF($A12="","",COUNTIFS(Evaluations!$G$3:$G$10000,$A12,Evaluations!$M$3:$M$10000,"پاسخ داده شده")) | F12: =IF($A12="","",IFERROR(COUNTIFS(Evaluations!$G$3:$G$10000,$A12,Evaluations!$O$3:$O$10000,"رعایت شده")/(COUNTIFS(Evaluations!$G$3:$G$10000,$A12,Evaluations!$O$3:$O$10000,"رعایت شده")+COUNTIFS(Evaluations!$G$3:$G$10000,$A12,Evaluations!$O$3:$O$10000,"رعایت نشده")),"")) | G12: =IF($A12="","",IFERROR(ROUND(100*COUNTIFS(Evaluations!$G$3:$G$10000,$A12,Evaluations!$Q$3:$Q$10000,1)/(COUNTIFS(Evaluations!$G$3:$G$10000,$A12,Evaluations!$Q$3:$Q$10000,1)+COUNTIFS(Evaluations!$G$3:$G$10000,$A12,Evaluations!$Q$3:$Q$10000,0)),2),"")) | H12: =IF($A12="","",IFERROR(ROUND(100*COUNTIFS(Evaluations!$G$3:$G$10000,$A12,Evaluations!$R$3:$R$10000,1)/(COUNTIFS(Evaluations!$G$3:$G$10000,$A12,Evaluations!$R$3:$R$10000,1)+COUNTIFS(Evaluations!$G$3:$G$10000,$A12,Evaluations!$R$3:$R$10000,0)),2),"")) | I12: =IF($A12="","",IFERROR(ROUND(100*COUNTIFS(Evaluations!$G$3:$G$10000,$A12,Evaluations!$S$3:$S$10000,1)/(COUNTIFS(Evaluations!$G$3:$G$10000,$A12,Evaluations!$S$3:$S$10000,1)+COUNTIFS(Evaluations!$G$3:$G$10000,$A12,Evaluations!$S$3:$S$10000,0)),2),"")) | J12: =IF($A12="","",IFERROR(ROUND(100*COUNTIFS(Evaluations!$G$3:$G$10000,$A12,Evaluations!$T$3:$T$10000,1)/(COUNTIFS(Evaluations!$G$3:$G$10000,$A12,Evaluations!$T$3:$T$10000,1)+COUNTIFS(Evaluations!$G$3:$G$10000,$A12,Evaluations!$T$3:$T$10000,0)),2),"")) | K12: =IF($A12="","",COUNTIFS(Evaluations!$G$3:$G$10000,$A12,Evaluations!$M$3:$M$10000,"عدم پاسخ")) | L12: =IF($A12="","",COUNTIFS(Evaluations!$G$3:$G$10000,$A12,Evaluations!$O$3:$O$10000,"رعایت نشده"))
B13: {=_xlfn.XLOOKUP(A13,DATA!D:D,DATA!E:E,"")} | C13: =IF($A13="","",COUNTIFS(Evaluations!$G$3:$G$10000,$A13,Evaluations!$U$3:$U$10000,">=0",Evaluations!$U$3:$U$10000,"<=100")) | D13: =IF(OR($A13="",C13=0),"",ROUND(SUMIFS(Evaluations!$U$3:$U$10000,Evaluations!$G$3:$G$10000,$A13)/C13,2)) | E13: =IF($A13="","",COUNTIFS(Evaluations!$G$3:$G$10000,$A13,Evaluations!$M$3:$M$10000,"پاسخ داده شده")) | F13: =IF($A13="","",IFERROR(COUNTIFS(Evaluations!$G$3:$G$10000,$A13,Evaluations!$O$3:$O$10000,"رعایت شده")/(COUNTIFS(Evaluations!$G$3:$G$10000,$A13,Evaluations!$O$3:$O$10000,"رعایت شده")+COUNTIFS(Evaluations!$G$3:$G$10000,$A13,Evaluations!$O$3:$O$10000,"رعایت نشده")),"")) | G13: =IF($A13="","",IFERROR(ROUND(100*COUNTIFS(Evaluations!$G$3:$G$10000,$A13,Evaluations!$Q$3:$Q$10000,1)/(COUNTIFS(Evaluations!$G$3:$G$10000,$A13,Evaluations!$Q$3:$Q$10000,1)+COUNTIFS(Evaluations!$G$3:$G$10000,$A13,Evaluations!$Q$3:$Q$10000,0)),2),"")) | H13: =IF($A13="","",IFERROR(ROUND(100*COUNTIFS(Evaluations!$G$3:$G$10000,$A13,Evaluations!$R$3:$R$10000,1)/(COUNTIFS(Evaluations!$G$3:$G$10000,$A13,Evaluations!$R$3:$R$10000,1)+COUNTIFS(Evaluations!$G$3:$G$10000,$A13,Evaluations!$R$3:$R$10000,0)),2),"")) | I13: =IF($A13="","",IFERROR(ROUND(100*COUNTIFS(Evaluations!$G$3:$G$10000,$A13,Evaluations!$S$3:$S$10000,1)/(COUNTIFS(Evaluations!$G$3:$G$10000,$A13,Evaluations!$S$3:$S$10000,1)+COUNTIFS(Evaluations!$G$3:$G$10000,$A13,Evaluations!$S$3:$S$10000,0)),2),"")) | J13: =IF($A13="","",IFERROR(ROUND(100*COUNTIFS(Evaluations!$G$3:$G$10000,$A13,Evaluations!$T$3:$T$10000,1)/(COUNTIFS(Evaluations!$G$3:$G$10000,$A13,Evaluations!$T$3:$T$10000,1)+COUNTIFS(Evaluations!$G$3:$G$10000,$A13,Evaluations!$T$3:$T$10000,0)),2),"")) | K13: =IF($A13="","",COUNTIFS(Evaluations!$G$3:$G$10000,$A13,Evaluations!$M$3:$M$10000,"عدم پاسخ")) | L13: =IF($A13="","",COUNTIFS(Evaluations!$G$3:$G$10000,$A13,Evaluations!$O$3:$O$10000,"رعایت نشده"))
... B489: {=_xlfn.XLOOKUP(A489,DATA!D:D,DATA!E:E,"")} | C489: =IF($A489="","",COUNTIFS(Evaluations!$G$3:$G$10000,$A489,Evaluations!$U$3:$U$10000,">=0",Evaluations!$U$3:$U$10000,"<=100")) | D489: =IF(OR($A489="",C489=0),"",ROUND(SUMIFS(Evaluations!$U$3:$U$10000,Evaluations!$G$3:$G$10000,$A489)/C489,2)) | E489: =IF($A489="","",COUNTIFS(Evaluations!$G$3:$G$10000,$A489,Evaluations!$M$3:$M$10000,"پاسخ داده شده")) | F489: =IF($A489="","",IFERROR(COUNTIFS(Evaluations!$G$3:$G$10000,$A489,Evaluations!$O$3:$O$10000,"رعایت شده")/(COUNTIFS(Evaluations!$G$3:$G$10000,$A489,Evaluations!$O$3:$O$10000,"رعایت شده")+COUNTIFS(Evaluations!$G$3:$G$10000,$A489,Evaluations!$O$3:$O$10000,"رعایت نشده")),"")) | G489: =IF($A489="","",IFERROR(ROUND(100*COUNTIFS(Evaluations!$G$3:$G$10000,$A489,Evaluations!$Q$3:$Q$10000,1)/(COUNTIFS(Evaluations!$G$3:$G$10000,$A489,Evaluations!$Q$3:$Q$10000,1)+COUNTIFS(Evaluations!$G$3:$G$10000,$A489,Evaluations!$Q$3:$Q$10000,0)),2),"")) | H489: =IF($A489="","",IFERROR(ROUND(100*COUNTIFS(Evaluations!$G$3:$G$10000,$A489,Evaluations!$R$3:$R$10000,1)/(COUNTIFS(Evaluations!$G$3:$G$10000,$A489,Evaluations!$R$3:$R$10000,1)+COUNTIFS(Evaluations!$G$3:$G$10000,$A489,Evaluations!$R$3:$R$10000,0)),2),"")) | I489: =IF($A489="","",IFERROR(ROUND(100*COUNTIFS(Evaluations!$G$3:$G$10000,$A489,Evaluations!$S$3:$S$10000,1)/(COUNTIFS(Evaluations!$G$3:$G$10000,$A489,Evaluations!$S$3:$S$10000,1)+COUNTIFS(Evaluations!$G$3:$G$10000,$A489,Evaluations!$S$3:$S$10000,0)),2),"")) | J489: =IF($A489="","",IFERROR(ROUND(100*COUNTIFS(Evaluations!$G$3:$G$10000,$A489,Evaluations!$T$3:$T$10000,1)/(COUNTIFS(Evaluations!$G$3:$G$10000,$A489,Evaluations!$T$3:$T$10000,1)+COUNTIFS(Evaluations!$G$3:$G$10000,$A489,Evaluations!$T$3:$T$10000,0)),2),"")) | K489: =IF($A489="","",COUNTIFS(Evaluations!$G$3:$G$10000,$A489,Evaluations!$M$3:$M$10000,"عدم پاسخ")) | L489: =IF($A489="","",COUNTIFS(Evaluations!$G$3:$G$10000,$A489,Evaluations!$O$3:$O$10000,"رعایت نشده"))
B490: {=_xlfn.XLOOKUP(A490,DATA!D:D,DATA!E:E,"")}
B491: {=_xlfn.XLOOKUP(A491,DATA!D:D,DATA!E:E,"")}
B492: {=_xlfn.XLOOKUP(A492,DATA!D:D,DATA!E:E,"")}
B493: {=_xlfn.XLOOKUP(A493,DATA!D:D,DATA!E:E,"")}
B494: {=_xlfn.XLOOKUP(A494,DATA!D:D,DATA!E:E,"")}
B495: {=_xlfn.XLOOKUP(A495,DATA!D:D,DATA!E:E,"")}
B496: {=_xlfn.XLOOKUP(A496,DATA!D:D,DATA!E:E,"")}
B497: {=_xlfn.XLOOKUP(A497,DATA!D:D,DATA!E:E,"")}
B498: {=_xlfn.XLOOKUP(A498,DATA!D:D,DATA!E:E,"")}
B499: {=_xlfn.XLOOKUP(A499,DATA!D:D,DATA!E:E,"")}
B500: {=_xlfn.XLOOKUP(A500,DATA!D:D,DATA!E:E,"")}
B501: {=_xlfn.XLOOKUP(A501,DATA!D:D,DATA!E:E,"")}
... B998: {=_xlfn.XLOOKUP(A998,DATA!D:D,DATA!E:E,"")}

Sheet Team Report
A1: نام تیم | B1: تعداد ارزیابی نمره‌دار | C1: تعداد کارشناسان ارزیابی‌شده | D1: میانگین نمره نهایی / 100 | E1: تعداد پیام پاسخ‌داده‌شده | F1: درصد رعایت SLA واقعی | G1: میانگین المان SLA / 100 | H1: میانگین پیگیری / 100 | I1: میانگین پایان‌بندی / 100 | J1: میانگین لحن / 100 | K1: تعداد عدم پاسخ | L1: تعداد SLA رعایت‌نشده | N1: {=UNIQUE(DATA!E:E)} -> Tele sales
A2: Tele sales | B2: =IF($A2="","",COUNTIFS(Evaluations!$H$3:$H$10000,$A2,Evaluations!$U$3:$U$10000,">=0",Evaluations!$U$3:$U$10000,"<=100")) -> 0 | C2: =IF($A2="","",COUNTIFS('Agent Report'!$B$4:$B$53,$A2,'Agent Report'!$C$4:$C$53,">0")) -> 0 | D2: =IF(OR($A2="",B2=0),"",ROUND(SUMIFS(Evaluations!$U$3:$U$10000,Evaluations!$H$3:$H$10000,$A2)/B2,2)) | E2: =IF($A2="","",COUNTIFS(Evaluations!$H$3:$H$10000,$A2,Evaluations!$M$3:$M$10000,"پاسخ داده شده")) -> 0 | F2: =IF($A2="","",IFERROR(COUNTIFS(Evaluations!$H$3:$H$10000,$A2,Evaluations!$O$3:$O$10000,"رعایت شده")/(COUNTIFS(Evaluations!$H$3:$H$10000,$A2,Evaluations!$O$3:$O$10000,"رعایت شده")+COUNTIFS(Evaluations!$H$3:$H$10000,$A2,Evaluations!$O$3:$O$10000,"رعایت نشده")),"")) | G2: =IF($A2="","",IFERROR(ROUND(100*COUNTIFS(Evaluations!$H$3:$H$10000,$A2,Evaluations!$Q$3:$Q$10000,1)/(COUNTIFS(Evaluations!$H$3:$H$10000,$A2,Evaluations!$Q$3:$Q$10000,1)+COUNTIFS(Evaluations!$H$3:$H$10000,$A2,Evaluations!$Q$3:$Q$10000,0)),2),"")) | H2: =IF($A2="","",IFERROR(ROUND(100*COUNTIFS(Evaluations!$H$3:$H$10000,$A2,Evaluations!$R$3:$R$10000,1)/(COUNTIFS(Evaluations!$H$3:$H$10000,$A2,Evaluations!$R$3:$R$10000,1)+COUNTIFS(Evaluations!$H$3:$H$10000,$A2,Evaluations!$R$3:$R$10000,0)),2),"")) | I2: =IF($A2="","",IFERROR(ROUND(100*COUNTIFS(Evaluations!$H$3:$H$10000,$A2,Evaluations!$S$3:$S$10000,1)/(COUNTIFS(Evaluations!$H$3:$H$10000,$A2,Evaluations!$S$3:$S$10000,1)+COUNTIFS(Evaluations!$H$3:$H$10000,$A2,Evaluations!$S$3:$S$10000,0)),2),"")) | J2: =IF($A2="","",IFERROR(ROUND(100*COUNTIFS(Evaluations!$H$3:$H$10000,$A2,Evaluations!$T$3:$T$10000,1)/(COUNTIFS(Evaluations!$H$3:$H$10000,$A2,Evaluations!$T$3:$T$10000,1)+COUNTIFS(Evaluations!$H$3:$H$10000,$A2,Evaluations!$T$3:$T$10000,0)),2),"")) | K2: =IF($A2="","",COUNTIFS(Evaluations!$H$3:$H$10000,$A2,Evaluations!$M$3:$M$10000,"عدم پاسخ")) -> 0 | L2: =IF($A2="","",COUNTIFS(Evaluations!$H$3:$H$10000,$A2,Evaluations!$O$3:$O$10000,"رعایت نشده")) -> 0 | N2: MLM
